Workbook

Sheet Lot_QC_Summary
B1: Lot_QC_Summary | C1: QC_Dictionary | D1: A_Replicates | E1: B_Replicates | F1: Density_Replicates | G1: A_Replicates_INCL | H1: A_Replicates_EXC | I1: Metric_Statistics | J1: A_Step_Replicates | K1: A_Step_Statistics | L1: Replicate_Flags | M1: Traceability
B2: HT-SYN Lot 종합 QC — 정책 INCLUSIVE
B3: Method A fingerprint·구조 이력, Method B 회복, 밀도를 Lot 단위로 통합했습니다. Strict = 60 s·Torque 10–95 % / Inclusive = 정책 허용 hold·범위 밖 점 포함. 상태는 데이터 품질 판정이며 제품 적합성(합격/불합격) 판정이 아닙니다.
B4: POLICY INCLUSIVE — accepted holds 30,45,60 s, 범위 밖 Torque 점 inclusive 포함. EXCEPTION·CENSORED 값은 표준 60 s Lot 통계·추세·규격 설정에 혼용 금지
B5: Lot 정보 및 데이터 범위
B6: Lot | C6: SYN
B7: 분석 정책 | C7: INCLUSIVE (hash 0a7fe4fd8ee0395a) | Lot 통계 모드 both | 대표 채널 inclusive | EXCEPTION separate | 상세 QCPolicy 시트
B8: Method A 반복 | C8: 1건 — 01:VALID
B9: Method B 반복 | C9: 없음 — T2 회복 지표 NO DATA
B10: 밀도 충전 | C10: 없음 — 밀도 입력 파일(--density-file) 미제공
B11: 고정 평가점 | C11: Low=0.5 rpm, Mid=2 rpm
B12: 고전단 평가점 | C12: 각 반복의 실제 측정 최고 RPM. 그 Step이 채널에서 부적격이면 NO VALUE
B13: 현재 Lot의 측정 최고 RPM | C13: 5.0 rpm
B14: 4 rpm | C14: 중간 측정점; 대표 고전단 기준 아님
B15: 분석기 | C15: HB-analysis-06-6 / LotQC-2.8 | 실행
B16: 무전단 안정화 | C16: 존재=True | Step S1 | 목표 RPM 0 | 목표 온도 25.0 °C | 목표 600.0 s | 실제 600.0 s | 평균 온도 25.0 °C | min 25.0 / max 25.0 | sampling 1.0 s | 상태 VALID | repeat 01 | 시료 이송 중 발생한 구조 교란 회복을 위한 무전단 안정화; 유동·H-B·SSI 계산에서는 제외
B18: 지표 층위 — 무엇을 말하고 무엇을 말하지 않는가
B19: T1 Lot 동일성 핵심 | C19: 매 Lot 비교의 1차 fingerprint. 조성·원료·혼합·탈포 편차를 가장 직접적으로 반영하며, 측정 정밀도가 확보된 직접 관측값 위주로 구성.
B20: T2 구조 이력·회복 | C20: 전단 이력에 대한 구조 붕괴와 재형성(요변성의 시간 측면). 원심 중 유동화와 원심 후 장벽 재겔화의 간접 지표.
B21: T3 모델·진단 | C21: 모델 외삽·파라미터 상관이 있는 파생값과 진단값. 개발·변경관리·이상조사용이며 기능 상관 검증 전 규격 사용 금지.
B22: DQ 데이터 품질 | C22: 측정 자체의 유효성(신호 크기·분해능·준평형·온도·정량 Step 수). 물성이 아니라 해당 Lot 값의 신뢰도를 말함.
B23: 지표별 Lot 통계 (숫자 열은 Metric_Statistics 수식 참조; 상태·사유는 Python 판정)
B24: 층위 | C24: Code | D24: Role | E24: 지표 | F24: 가리키는 물성 | G24: 단위 | H24: 유효 n / 전체 | I24: Mean | J24: SD | K24: RSD(%) | L24: Min | M24: Max | N24: Range | O24: Mean |SD| | P24: 부호 +/− | Q24: 대표 채널 | R24: n EXC | S24: n CENS | T24: n Low-TQ Ref | U24: n High-TQ Ref | V24: 반복성 규칙(임시) | W24: GOOD ≤ | X24: REVIEW ≤ | Y24: 반복성 상태 | Z24: 적용 RPM | AA24: 적용 shear rate | AB24: 기여 Step | AC24: 적용 저점 RPM | AD24: 적용 고점 RPM | AE24: 적용 저점 Step | AF24: 적용 고점 Step | AG24: 적용 저점 shear rate | AH24: 적용 고점 shear rate | AI24: 선택 규칙 | AJ24: 분자 RPM | AK24: 분모 RPM | AL24: 분자 Step | AM24: 분모 Step | AN24: 분자 shear rate | AO24: 분모 shear rate | AP24: 실제 RPM 배율 | AQ24: source type | AR24: Included in Lot stats | AS24: Lot-stat exclusion reason | AT24: 값 상태 | AU24: 데이터 상태 | AV24: 합격성 반영 | AW24: 비고·제외 근거(반복)
B25: T1 Lot 동일성 핵심 | C25: A_TAU_L_UP | D25: CORE | E25: 저전단 구조 저항 τ↑(0.5 rpm) | F25: 휴지 중 형성된 실리카·겔화제 네트워크가 최저 정량 전단에서 흐름에 저항하는 크기(저전단 구조강도의 상대값). | G25: Pa | H25: 1 / 1 | I25: 200 | L25: 200 | M25: 200 | N25: 0 | O25: 200 | P25: +1/−0 | Q25: INCLUSIVE | R25: 0 | S25: 0 | T25: 0 | U25: 0 | V25: RSD | W25: 10 | X25: 20 | Y25: =IF(OR(V25="-",H25<2),"N/A",IF(V25="RSD",IF(ISNUMBER(K25),IF(K25<=W25,"GOOD",IF(K25<=X25,"REVIEW","HIGH VAR")),"HIGH VAR"),IF(J25<=W25,"GOOD",IF(J25<=X25,"REVIEW","HIGH VAR")))) | Z25: 0.5 | AA25: 1 | AB25: S4 | AC25: 0.5 | AE25: S4 | AG25: 1 | AI25: fixed low reference 0.5 rpm | AR25: Yes | AT25: strict 정량값 | AU25: VALID | AV25: ELIGIBLE | AW25: INCLUSIVE | strict 정량값 | 60 s hold, Torque 10–95% 범위 내 | Steps S4 | RPM 0.5 | γ̇ 1 | fixed low reference 0.5 rpm
B26: T1 Lot 동일성 핵심 | C26: A_TAU_M_UP | D26: CORE | E26: 중간 전단 유동 저항 τ↑(2 rpm) | F26: 구조 일부가 전단으로 해체된 상태의 유동 저항. 측정창 중 Torque 여유가 커 반복 정밀도가 가장 좋은 기준점. | G26: Pa | H26: 1 / 1 | I26: 200 | L26: 200 | M26: 200 | N26: 0 | O26: 200 | P26: +1/−0 | Q26: INCLUSIVE | R26: 0 | S26: 0 | T26: 0 | U26: 0 | V26: RSD | W26: 10 | X26: 20 | Y26: =IF(OR(V26="-",H26<2),"N/A",IF(V26="RSD",IF(ISNUMBER(K26),IF(K26<=W26,"GOOD",IF(K26<=X26,"REVIEW","HIGH VAR")),"HIGH VAR"),IF(J26<=W26,"GOOD",IF(J26<=X26,"REVIEW","HIGH VAR")))) | Z26: 2.0 | AA26: 4 | AB26: S8 | AI26: fixed mid reference 2.0 rpm | AR26: Yes | AT26: strict 정량값 | AU26: VALID | AV26: ELIGIBLE | AW26: INCLUSIVE | strict 정량값 | 60 s hold, Torque 10–95% 범위 내 | Steps S8 | RPM 2.0 | γ̇ 4 | fixed mid reference 2.0 rpm
B27: T1 Lot 동일성 핵심 | C27: A_TAU_H_UP | D27: CORE | E27: 고전단 유동 저항 (실제 최고 RPM) | F27: 그 측정에서 실제로 도달한 최고 전단의 유동 저항. | G27: Pa | H27: 1 / 1 | I27: 200 | L27: 200 | M27: 200 | N27: 0 | O27: 200 | P27: +1/−0 | Q27: INCLUSIVE | R27: 0 | S27: 0 | T27: 0 | U27: 0 | V27: RSD | W27: 10 | X27: 20 | Y27: =IF(OR(V27="-",H27<2),"N/A",IF(V27="RSD",IF(ISNUMBER(K27),IF(K27<=W27,"GOOD",IF(K27<=X27,"REVIEW","HIGH VAR")),"HIGH VAR"),IF(J27<=W27,"GOOD",IF(J27<=X27,"REVIEW","HIGH VAR")))) | Z27: 5.0 | AA27: 10 | AB27: S11 | AD27: 5 | AF27: S11 | AH27: 10 | AI27: actual measured maximum RPM | AR27: Yes | AT27: strict 정량값 | AU27: VALID | AV27: ELIGIBLE | AW27: INCLUSIVE | strict 정량값 | 60 s hold, Torque 10–95% 범위 내 | Steps S11 | RPM 5.0 | γ̇ 10 | actual measured maximum RPM | [OK] 실제 최고 RPM 5.0 rpm, Step S11, shear rate 10 s⁻¹; 5.0 rpm Step S11 사용 (01)
B28: T1 Lot 동일성 핵심 | C28: A_ETA_MIN_UP | D28: CORE | E28: 최저 측정 RPM 겉보기 점도 — 상승 | F28: 상승 경로에서 가장 낮은 전단의 겉보기 점도. | G28: cP | H28: 1 / 1 | I28: 500000 | L28: 500000 | M28: 500000 | N28: 0 | O28: 500000 | P28: +1/−0 | Q28: INCLUSIVE | R28: 0 | S28: 0 | T28: 0 | U28: 0 | V28: RSD | W28: 10 | X28: 20 | Y28: =IF(OR(V28="-",H28<2),"N/A",IF(V28="RSD",IF(ISNUMBER(K28),IF(K28<=W28,"GOOD",IF(K28<=X28,"REVIEW","HIGH VAR")),"HIGH VAR"),IF(J28<=W28,"GOOD",IF(J28<=X28,"REVIEW","HIGH VAR")))) | Z28: 0.2 | AA28: 0.4 | AB28: S2 | AC28: 0.2 | AE28: S2 | AG28: 0.4 | AI28: actual minimum measured eligible Up RPM; fixed low reference 0.5 rpm이 아님 | AR28: Yes | AT28: strict 정량값 | AU28: VALID | AV28: ELIGIBLE | AW28: INCLUSIVE | strict 정량값 | 60 s hold, Torque 10–95% 범위 내 | Steps S2 | RPM 0.2 | γ̇ 0.4 | actual minimum measured eligible Up RPM; fixed low reference 0.5 rpm이 아님
B29: T1 Lot 동일성 핵심 | C29: A_ETA_HIGH | D29: CORE | E29: 고전단 겉보기 점도 (실제 최고 RPM) | F29: 프로그램 최고 전단에서의 겉보기 점도. | G29: cP | H29: 1 / 1 | I29: 20000 | L29: 20000 | M29: 20000 | N29: 0 | O29: 20000 | P29: +1/−0 | Q29: INCLUSIVE | R29: 0 | S29: 0 | T29: 0 | U29: 0 | V29: RSD | W29: 10 | X29: 20 | Y29: =IF(OR(V29="-",H29<2),"N/A",IF(V29="RSD",IF(ISNUMBER(K29),IF(K29<=W29,"GOOD",IF(K29<=X29,"REVIEW","HIGH VAR")),"HIGH VAR"),IF(J29<=W29,"GOOD",IF(J29<=X29,"REVIEW","HIGH VAR")))) | Z29: 5.0 | AA29: 10 | AB29: S11 | AD29: 5 | AF29: S11 | AH29: 10 | AI29: actual measured maximum RPM | AR29: Yes | AT29: strict 정량값 | AU29: VALID | AV29: ELIGIBLE | AW29: INCLUSIVE | strict 정량값 | 60 s hold, Torque 10–95% 범위 내 | Steps S11 | RPM 5.0 | γ̇ 10 | actual measured maximum RPM | [OK] 실제 최고 RPM 5.0 rpm, Step S11, shear rate 10 s⁻¹ (01)
B30: T1 Lot 동일성 핵심 | C30: A_SSI_FIELD_0P2_2 | D30: CORE | E30: 현장 SSI (0.2/2 rpm) | F30: 현장 전단박화 지수. 정확한 0.2 rpm과 2.0 rpm Up 대표 점도의 비. | G30: - | H30: 1 / 1 | I30: 10 | L30: 10 | M30: 10 | N30: 0 | O30: 10 | P30: +1/−0 | Q30: INCLUSIVE | R30: 0 | S30: 0 | T30: 0 | U30: 0 | V30: RSD | W30: 10 | X30: 20 | Y30: =IF(OR(V30="-",H30<2),"N/A",IF(V30="RSD",IF(ISNUMBER(K30),IF(K30<=W30,"GOOD",IF(K30<=X30,"REVIEW","HIGH VAR")),"HIGH VAR"),IF(J30<=W30,"GOOD",IF(J30<=X30,"REVIEW","HIGH VAR")))) | Z30: 0.2,2 | AA30: 0.4,4 | AB30: S2,S8 | AC30: 0.2 | AD30: 2 | AE30: S2 | AF30: S8 | AI30: exact measured Up 0.2 rpm / exact measured Up 2.0 rpm | AJ30: 0.2 | AK30: 2.0 | AL30: S2 | AM30: S8 | AN30: 0.4 | AO30: 4 | AP30: 10 | AQ30: measured | AR30: Yes | AT30: strict 정량값 | AU30: VALID | AV30: ELIGIBLE | AW30: INCLUSIVE | strict 정량값 | 60 s hold, Torque 10–95% 범위 내 | Steps S2,S8 | RPM 0.2,2 | γ̇ 0.4,4 | exact measured Up 0.2 rpm / exact measured Up 2.0 rpm | [OK] eta_up(0.2 rpm, S2) / eta(2 rpm, Up endpoint S8) (01)
B31: T1 Lot 동일성 핵심 | C31: A_SSI_QC_0P5_5 | D31: CORE | E31: Step-flow QC SSI (0.5/5 rpm) | F31: Step-flow QC 전단박화 지수. 정확한 0.5 rpm Up과 5.0 rpm endpoint의 비. | G31: - | H31: 1 / 1 | I31: 10 | L31: 10 | M31: 10 | N31: 0 | O31: 10 | P31: +1/−0 | Q31: INCLUSIVE | R31: 0 | S31: 0 | T31: 0 | U31: 0 | V31: RSD | W31: 10 | X31: 20 | Y31: =IF(OR(V31="-",H31<2),"N/A",IF(V31="RSD",IF(ISNUMBER(K31),IF(K31<=W31,"GOOD",IF(K31<=X31,"REVIEW","HIGH VAR")),"HIGH VAR"),IF(J31<=W31,"GOOD",IF(J31<=X31,"REVIEW","HIGH VAR")))) | Z31: 0.5,5 | AA31: 1,10 | AB31: S4,S11 | AC31: 0.5 | AD31: 5 | AE31: S4 | AF31: S11 | AI31: exact measured Up 0.5 rpm / exact measured 5.0 rpm Up endpoint or shared turnaround | AJ31: 0.5 | AK31: 5.0 | AL31: S4 | AM31: S11 | AN31: 1 | AO31: 10 | AP31: 10 | AQ31: measured | AR31: Yes | AT31: strict 정량값 | AU31: VALID | AV31: ELIGIBLE | AW31: INCLUSIVE | strict 정량값 | 60 s hold, Torque 10–95% 범위 내 | Steps S4,S11 | RPM 0.5,5 | γ̇ 1,10 | exact measured Up 0.5 rpm / exact measured 5.0 rpm Up endpoint or shared turnaround | [OK] eta_up(0.5 rpm, S4) / eta(5 rpm, Up endpoint S11) (01)
B32: T1 Lot 동일성 핵심 | C32: A_ETA_LOW_DN | D32: CORE | E32: 저전단 겉보기 점도 — 하강 | F32: 고전단 이력 후 가장 낮은 하강 전단의 겉보기 점도. | G32: cP | H32: 0 / 1 | Q32: INCLUSIVE | R32: 0 | S32: 0 | T32: 0 | U32: 0 | V32: RSD | W32: 10 | X32: 20 | Y32: =IF(OR(V32="-",H32<2),"N/A",IF(V32="RSD",IF(ISNUMBER(K32),IF(K32<=W32,"GOOD",IF(K32<=X32,"REVIEW","HIGH VAR")),"HIGH VAR"),IF(J32<=W32,"GOOD",IF(J32<=X32,"REVIEW","HIGH VAR")))) | AR32: No | AS32: Down 분석 가능 Step 없음 | AT32: NO VALUE | AU32: NO VALUE | AV32: EXCLUDED | AW32: INCLUSIVE | NO VALUE | [NO VALUE] Down 분석 가능 Step 없음 (01)
B33: T1 Lot 동일성 핵심 | C33: D_RHO25 | D33: CORE | E33: 25 °C 탈포 젤 겉보기 밀도 ρ25 | F33: 젤 단위 부피당 질량. 수지·가소제 대 실리카 등 충전재의 배합비와 잔류 기포량이 합쳐진 값. | G33: g/mL | H33: 0 / 0 | Q33: STRICT | R33: 0 | S33: 0 | T33: 0 | U33: 0 | V33: SD | W33: 0.002 | X33: 0.005 | Y33: =IF(OR(V33="-",H33<2),"N/A",IF(V33="RSD",IF(ISNUMBER(K33),IF(K33<=W33,"GOOD",IF(K33<=X33,"REVIEW","HIGH VAR")),"HIGH VAR"),IF(J33<=W33,"GOOD",IF(J33<=X33,"REVIEW","HIGH VAR")))) | AR33: No | AT33: NO VALUE | AU33: NO DATA | AV33: NO DATA | AW33: STRICT | NO VALUE
B34: T2 구조 이력·회복 | C34: A_DU_L | D34: PROCESS_SENSITIVE | E34: 저전단 잔류 구조율 D/U(0.5 rpm) | F34: 최고 전단 이력 후 하강 경로에서 같은 저전단으로 돌아왔을 때 남아 있거나 재형성된 구조의 비율(Method A 시간척도). | G34: % | H34: 0 / 1 | Q34: INCLUSIVE | R34: 0 | S34: 0 | T34: 0 | U34: 0 | V34: SD | W34: 2 | X34: 5 | Y34: =IF(OR(V34="-",H34<2),"N/A",IF(V34="RSD",IF(ISNUMBER(K34),IF(K34<=W34,"GOOD",IF(K34<=X34,"REVIEW","HIGH VAR")),"HIGH VAR"),IF(J34<=W34,"GOOD",IF(J34<=X34,"REVIEW","HIGH VAR")))) | AR34: No | AS34: S4 Up 0.5 rpm; Down 0.5 rpm Step 없음 | AT34: strict 정량값 | AU34: NO VALUE | AV34: EXCLUDED | AW34: INCLUSIVE | strict 정량값 | 60 s hold, Torque 10–95% 범위 내 | [NO VALUE] S4 Up 0.5 rpm; Down 0.5 rpm Step 없음 (01)
B35: T2 구조 이력·회복 | C35: A_DU_M | D35: PROCESS_SENSITIVE | E35: 중간 전단 잔류 구조율 D/U(2 rpm) | F35: 중간 전단에서 고전단 이력 전후 유동 저항의 비. 저전단 D/U보다 Torque 여유가 커 정밀도가 좋음. | G35: % | H35: 0 / 1 | Q35: INCLUSIVE | R35: 0 | S35: 0 | T35: 0 | U35: 0 | V35: SD | W35: 2 | X35: 5 | Y35: =IF(OR(V35="-",H35<2),"N/A",IF(V35="RSD",IF(ISNUMBER(K35),IF(K35<=W35,"GOOD",IF(K35<=X35,"REVIEW","HIGH VAR")),"HIGH VAR"),IF(J35<=W35,"GOOD",IF(J35<=X35,"REVIEW","HIGH VAR")))) | AR35: No | AS35: S8 Up 2 rpm; Down 2 rpm Step 없음 | AT35: strict 정량값 | AU35: NO VALUE | AV35: EXCLUDED | AW35: INCLUSIVE | strict 정량값 | 60 s hold, Torque 10–95% 범위 내 | [NO VALUE] S8 Up 2 rpm; Down 2 rpm Step 없음 (01)
B36: T2 구조 이력·회복 | C36: A_HYS_REL | D36: PROCESS_SENSITIVE | E36: 상대 응력 히스테리시스 | F36: 상승·하강 경로 전체에서 전단 이력으로 생긴 곡선 차이의 정규화 크기(구조 붕괴와 재구축의 불균형 총량). | G36: % | H36: 0 / 1 | Q36: INCLUSIVE | R36: 0 | S36: 0 | T36: 0 | U36: 0 | V36: SD | W36: 1 | X36: 2 | Y36: =IF(OR(V36="-",H36<2),"N/A",IF(V36="RSD",IF(ISNUMBER(K36),IF(K36<=W36,"GOOD",IF(K36<=X36,"REVIEW","HIGH VAR")),"HIGH VAR"),IF(J36<=W36,"GOOD",IF(J36<=X36,"REVIEW","HIGH VAR")))) | AR36: No | AS36: 공통 전단률 0쌍 | Full H-B only; no paired point for hysteresis: S2 0.2 rpm, S3 0.35 rpm, S4 0.5 rpm, S5 0.7 rpm, S6 1 rpm, S7 1.5 rpm, S8 2 rpm, S9 3 rpm, S10 4 rpm, S11 5 rpm | AT36: NO VALUE | AU36: NO VALUE | AV36: EXCLUDED | AW36: INCLUSIVE | NO VALUE | [NO VALUE] 공통 전단률 0쌍 | Full H-B only; no paired point for hysteresis: S2 0.2 rpm, S3 0.35 rpm, S4 0.5 rpm, S5 0.7 rpm, S6 1 rpm, S7 1.5 rpm, S8 2 rpm, S9 3 rpm, S10 4 rpm, S11 5 rpm (01)
B37: T2 구조 이력·회복 | C37: A_BRK_PEAK | D37: PROCESS_SENSITIVE | E37: 최고 전단 Step 내 구조 붕괴율 | F37: 일정한 고전단 유지 중 시간에 따라 구조가 계속 해체되는 정도(요변성의 붕괴 측면). 0 % 기준의 차이형 지표. | G37: % | H37: 1 / 1 | I37: 0 | L37: 0 | M37: 0 | N37: 0 | O37: 0 | P37: +0/−0/0×1 | Q37: INCLUSIVE | R37: 0 | S37: 0 | T37: 0 | U37: 0 | V37: SD | W37: 1 | X37: 2 | Y37: =IF(OR(V37="-",H37<2),"N/A",IF(V37="RSD",IF(ISNUMBER(K37),IF(K37<=W37,"GOOD",IF(K37<=X37,"REVIEW","HIGH VAR")),"HIGH VAR"),IF(J37<=W37,"GOOD",IF(J37<=X37,"REVIEW","HIGH VAR")))) | AR37: Yes | AT37: strict 정량값 | AU37: VALID | AV37: ELIGIBLE | AW37: INCLUSIVE | strict 정량값 | 60 s hold, Torque 10–95% 범위 내
B38: T2 구조 이력·회복 | C38: A_STATIC_YIELD_APPROX_UP | D38: PROCESS_SENSITIVE | E38: 근사 정적 항복응력 — 상승 Start-up | F38: 초기 저전단에서 흐름이 시작될 때의 응력 피크. A_OVS_L(초과율 %)과 다른 절대 응력이다. | G38: Pa | H38: 1 / 1 | I38: 200 | L38: 200 | M38: 200 | N38: 0 | O38: 200 | P38: +1/−0 | Q38: INCLUSIVE | R38: 0 | S38: 0 | T38: 0 | U38: 0 | V38: RSD | W38: 15 | X38: 30 | Y38: =IF(OR(V38="-",H38<2),"N/A",IF(V38="RSD",IF(ISNUMBER(K38),IF(K38<=W38,"GOOD",IF(K38<=X38,"REVIEW","HIGH VAR")),"HIGH VAR"),IF(J38<=W38,"GOOD",IF(J38<=X38,"REVIEW","HIGH VAR")))) | Z38: 0.2 | AA38: 0.4 | AB38: S2 | AC38: 0.2 | AE38: S2 | AG38: 0.4 | AI38: actual minimum measured eligible Up RPM; fixed low reference 0.5 rpm이 아님 | AR38: Yes | AT38: strict 정량값 | AU38: VALID | AV38: ELIGIBLE | AW38: INCLUSIVE | strict 정량값 | 60 s hold, Torque 10–95% 범위 내 | Steps S2 | RPM 0.2 | γ̇ 0.4 | actual minimum measured eligible Up RPM; fixed low reference 0.5 rpm이 아님
B39: T2 구조 이력·회복 | C39: A_POST_SHEAR_STARTUP_STRESS | D39: PROCESS_SENSITIVE | E39: Post-shear residual start-up stress | F39: 고전단 이력 후 저전단으로 돌아왔을 때의 잔류 개시 응력. | G39: Pa | H39: 0 / 1 | Q39: INCLUSIVE | R39: 0 | S39: 0 | T39: 0 | U39: 0 | V39: RSD | W39: 15 | X39: 30 | Y39: =IF(OR(V39="-",H39<2),"N/A",IF(V39="RSD",IF(ISNUMBER(K39),IF(K39<=W39,"GOOD",IF(K39<=X39,"REVIEW","HIGH VAR")),"HIGH VAR"),IF(J39<=W39,"GOOD",IF(J39<=X39,"REVIEW","HIGH VAR")))) | AR39: No | AS39: Down 분석 가능 Step 없음 | AT39: NO VALUE | AU39: NO VALUE | AV39: EXCLUDED | AW39: INCLUSIVE | NO VALUE | [NO VALUE] Down 분석 가능 Step 없음 (01)
B40: T2 구조 이력·회복 | C40: A_POST_SHEAR_STRESS_RETENTION | D40: PROCESS_SENSITIVE | E40: Post-shear stress retention | F40: 같은 저전단에서 고전단 이력 전후 개시 응력의 유지 비율. | G40: % | H40: 0 / 1 | Q40: INCLUSIVE | R40: 0 | S40: 0 | T40: 0 | U40: 0 | V40: SD | W40: 5 | X40: 10 | Y40: =IF(OR(V40="-",H40<2),"N/A",IF(V40="RSD",IF(ISNUMBER(K40),IF(K40<=W40,"GOOD",IF(K40<=X40,"REVIEW","HIGH VAR")),"HIGH VAR"),IF(J40<=W40,"GOOD",IF(J40<=X40,"REVIEW","HIGH VAR")))) | AR40: No | AS40: 공통 RPM 없음 — 보간하지 않음 | AT40: NO VALUE | AU40: NO VALUE | AV40: EXCLUDED | AW40: INCLUSIVE | NO VALUE | [NO VALUE] 공통 RPM 없음 — 보간하지 않음 (01)
B41: T2 구조 이력·회복 | C41: A_ETA_RECOVERY_LOW | D41: PROCESS_SENSITIVE | E41: 점도 회복률 — 최저 공통 RPM | F41: 최저 공통 전단에서의 겉보기 점도 회복률. | G41: % | H41: 0 / 1 | Q41: INCLUSIVE | R41: 0 | S41: 0 | T41: 0 | U41: 0 | V41: SD | W41: 3 | X41: 6 | Y41: =IF(OR(V41="-",H41<2),"N/A",IF(V41="RSD",IF(ISNUMBER(K41),IF(K41<=W41,"GOOD",IF(K41<=X41,"REVIEW","HIGH VAR")),"HIGH VAR"),IF(J41<=W41,"GOOD",IF(J41<=X41,"REVIEW","HIGH VAR")))) | AR41: No | AS41: 공통 RPM 없음 — 보간하지 않음 | AT41: NO VALUE | AU41: NO VALUE | AV41: EXCLUDED | AW41: INCLUSIVE | NO VALUE | [NO VALUE] 공통 RPM 없음 — 보간하지 않음 (01)
...

Sheet QC_Dictionary
B1: Lot_QC_Summary | C1: QC_Dictionary | D1: A_Replicates | E1: B_Replicates | F1: Density_Replicates | G1: A_Replicates_INCL | H1: A_Replicates_EXC | I1: Metric_Statistics | J1: A_Step_Replicates | K1: A_Step_Statistics | L1: Replicate_Flags | M1: Traceability
B2: QC_Dictionary — 각 QC 지표가 가리키는 물성과 해석
B3: 정의·계산식, 가리키는 물성, SST 기능 단계 연결, 값 증감의 의미, 이 지표가 말하지 않는 것(한계), 유효 조건.
B5: 층위 | C5: Code | D5: Role / 합격성 | E5: 지표 | F5: 단위 | G5: 정의·계산식 | H5: 가리키는 물성 | I5: SST 기능 연결 | J5: 값이 높아질 때 | K5: 값이 낮아질 때 | L5: 해석 한계(말하지 않는 것) | M5: 유효 조건 | N5: 반복성 규칙(임시)
B6: T1 Lot 동일성 핵심 | C6: A_TAU_L_UP | D6: CORE / 합격성 O | E6: 저전단 구조 저항 τ↑(0.5 rpm) | F6: Pa | G6: Method A Up 경로 0.5 rpm(γ̇=1 s⁻¹) Step 대표 전단응력. | H6: 휴지 중 형성된 실리카·겔화제 네트워크가 최저 정량 전단에서 흐름에 저항하는 크기(저전단 구조강도의 상대값). | I6: 보관·운송 중 튜브 바닥 형태 유지, 원심 초기 유동 개시 저항. | J6: 네트워크 강화(겔화제 과다, 냉각 이력에 따른 결정성 구조 등) 가능. 원심 중 이동 개시 지연 여부 확인. | K6: 구조 약화 가능. 보관·운송 중 흘러내림·경사 유동 여부 확인. | L6: 이미 흐르고 있는 상태의 값이며 정적 항복응력이 아님. 고정 저전단 평가점은 0.5 rpm이다. 0.35 rpm은 Full H-B 확장점이며 이 지표를 대체하지 않는다. H-B fitting 입력 RPM을 제한하지 않는다. Torque가 10% 부근이면 0.1% 표시 단위가 약 1% 상대오차에 해당(A_RES_L 참조). | M6: 60초 회전 Step·후반 10초·Torque 10–95% 유효점만 사용. 미충족 시 공란(대체값 없음). | N6: RSD: GOOD ≤10, REVIEW ≤20
B7: T1 Lot 동일성 핵심 | C7: A_TAU_M_UP | D7: CORE / 합격성 O | E7: 중간 전단 유동 저항 τ↑(2 rpm) | F7: Pa | G7: Method A Up 경로 2 rpm(γ̇=4 s⁻¹) Step 대표 전단응력. | H7: 구조 일부가 전단으로 해체된 상태의 유동 저항. 측정창 중 Torque 여유가 커 반복 정밀도가 가장 좋은 기준점. | I7: 충전·이송 및 원심 중 젤 이동 과정의 대표 유동성(Lot 간 상대 비교). | J7: 배합 점도 상승, 충전재 증가 또는 분산 불량(응집) 가능. | K7: 가소제 과다, 네트워크 형성 부족 가능. | L7: 실제 원심분리 전단률보다 훨씬 낮은 조건. 절대 이동속도의 예측값이 아님. | M7: 60초 회전 Step·후반 10초·Torque 10–95% 유효점만 사용. 미충족 시 공란(대체값 없음). | N7: RSD: GOOD ≤10, REVIEW ≤20
B8: T1 Lot 동일성 핵심 | C8: A_TAU_H_UP | D8: CORE / 합격성 O | E8: 고전단 유동 저항 (실제 최고 RPM) | F8: Pa | G8: Up 또는 공유 turnaround 중 해당 채널에서 유효한 측정 최고 RPM Step의 대표 전단응력. 더 높은 RPM이 부적격하면 낮은 RPM으로 대체하지 않고 NO VALUE. | H8: 그 측정에서 실제로 도달한 최고 전단의 유동 저항. | I8: 원심 중 이동성 방향의 대리지표. | J8: 매트릭스 점도 상승 또는 충전재 증가. | K8: 매트릭스 점도 저하. | L8: 5 rpm이 측정되면 4 rpm 응력을 이 지표로 보고하지 않는다. 4 rpm은 중간 측정점이다. | M8: 60초 회전 Step·후반 10초·Torque 10–95% 유효점만 사용. 미충족 시 공란(대체값 없음). | N8: RSD: GOOD ≤10, REVIEW ≤20
B9: T1 Lot 동일성 핵심 | C9: A_ETA_MIN_UP | D9: CORE / 합격성 O | E9: 최저 측정 RPM 겉보기 점도 — 상승 | F9: cP | G9: 분석 가능한 Up Step 중 실제 최저 RPM의 대표 겉보기 점도. 실제 최저 측정 RPM 사용; SSI의 고정 0.5 rpm 분자와 다름. | H9: 상승 경로에서 가장 낮은 전단의 겉보기 점도. | I9: 휴지 구조가 흐름에 저항하는 점성 크기. | J9: 저전단 저항 증가. | K9: 저전단 저항 감소. | L9: 실제 최저 측정 RPM 사용; SSI의 고정 0.5 rpm 분자와 다름. 0.35 rpm이 있으면 그 점도를 쓴다. 최저 RPM이 반복마다 다르면 Lot 통계는 REVIEW. | M9: 60초 회전 Step·후반 10초·Torque 10–95% 유효점만 사용. 미충족 시 공란(대체값 없음). | N9: RSD: GOOD ≤10, REVIEW ≤20
B10: T1 Lot 동일성 핵심 | C10: A_ETA_HIGH | D10: CORE / 합격성 O | E10: 고전단 겉보기 점도 (실제 최고 RPM) | F10: cP | G10: 해당 채널에서 사용 가능한 실제 최고 RPM Step의 겉보기 점도. 한 번만 측정되면 공유 turnaround 점도를 A_ETA_HIGH에만 기록하고, 더 높은 RPM이 부적격하면 낮은 RPM으로 대체하지 않는다. | H10: 프로그램 최고 전단에서의 겉보기 점도. | I10: 원심에 가까운 고전단 유동 저항. | J10: 고전단 저항 큼. | K10: 고전단 저항 작음. | L10: 최고 RPM이 Up과 Down에 각각 따로 측정되면 A_ETA_HIGH_UP/DN을 따로 본다. 단일 turnaround 값은 복제하지 않는다. 4 rpm reference로 대체하지 않는다. | M10: 60초 회전 Step·후반 10초·Torque 10–95% 유효점만 사용. 미충족 시 공란(대체값 없음). | N10: RSD: GOOD ≤10, REVIEW ≤20
B11: T1 Lot 동일성 핵심 | C11: A_SSI_FIELD_0P2_2 | D11: CORE / 합격성 O | E11: 현장 전단박화 지수 SSI (0.2/2 rpm) | F11: - | G11: eta_up(0.2 rpm) / eta_up(2.0 rpm) | H11: 현장 전단박화 지수. 정확한 0.2 rpm과 2.0 rpm Up 대표 점도의 비. | I11: 저전단 구조 대비 2 rpm 유동화. | J11: 0.2 rpm 대비 2 rpm 점도가 낮음. | K11: 뉴턴 거동에 가까워짐. | L11: 0.2 대신 0.35 또는 0.5를 쓰지 않는다. 2.0 대신 1.5 또는 3.0을 쓰지 않는다. 보간·모델값 금지. | M11: 같은 채널에서 두 실측 Up Step representative가 존재해야 한다. 다른 RPM, 보간값 또는 모델값으로 대체하지 않는다. | N11: RSD: GOOD ≤10, REVIEW ≤20
B12: T1 Lot 동일성 핵심 | C12: A_SSI_QC_0P5_5 | D12: CORE / 합격성 O | E12: Step-flow QC 전단박화 지수 SSI (0.5/5 rpm) | F12: - | G12: eta_up(0.5 rpm) / eta(5.0 rpm Up endpoint 또는 실제 shared turnaround) | H12: Step-flow QC 전단박화 지수. 정확한 0.5 rpm Up과 5.0 rpm endpoint의 비. | I12: 0.5 rpm 구조 대비 5 rpm 유동화. | J12: 0.5 rpm 대비 5 rpm 점도가 낮음. | K12: 뉴턴 거동에 가까워짐. | L12: 0.5 대신 0.35를 쓰지 않는다. 5.0 대신 4.0을 쓰지 않는다. 실제 최저/최고 RPM 비율로 정의를 바꾸지 않는다. | M12: 같은 채널에서 두 실측 Step representative가 존재해야 한다. 0.35 또는 4 rpm으로 대체하지 않는다. | N12: RSD: GOOD ≤10, REVIEW ≤20
B13: T1 Lot 동일성 핵심 | C13: REST_STABILIZATION | D13: CORE / 합격성 O | E13: 무전단 구조 안정화 | F13: - | G13: 0 rpm, 25 °C, 목표 600초 | H13: 0 rpm, 25 °C, 목표 600초. 시료 이송 중 구조 교란 회복을 위한 전처리 구간. 유동·H-B·SSI 계산에서는 제외한다. | I13: 측정 위치로 옮기는 동안 생긴 구조 교란을 유동 측정 전에 회복한다. | J13: — | K13: — | L13: moving Step, SSI 후보, H-B 후보, hysteresis 후보가 아니다. | M13: 유동 지표에서는 제외하고 시험 전처리 QC로만 평가한다. | N13: —
B14: T1 Lot 동일성 핵심 | C14: A_SSI_DECADE | D14: CORE / 합격성 O | E14: 실측 10배 RPM 점도비 SSI | F14: - | G14: eta(low RPM) / eta(high RPM), high RPM / low RPM = 10 within configured tolerance | H14: 프로토콜에서 실제로 측정된 10배 RPM 쌍의 점도비. pair_id별 독립 지표. | I14: 공식 0.2/2, 0.5/5 이외의 실측 decade 쌍을 프로토콜 변경에 맞춰 보존한다. | J14: 저점 대비 고점 점도가 낮음. | K14: 뉴턴 거동에 가까워짐. | L14: 서로 다른 pair를 같은 Lot 통계에 혼합하지 않는다. 0 rpm pair는 만들지 않는다. 0.35/4는 decade가 아니다. | M14: pair_id별 독립 지표로 관리한다. 서로 다른 pair를 같은 Lot 통계에 혼합하지 않는다. | N14: RSD: GOOD ≤10, REVIEW ≤20
B15: T1 Lot 동일성 핵심 | C15: A_ETA_LOW_DN | D15: CORE / 합격성 O | E15: 저전단 겉보기 점도 — 하강 | F15: cP | G15: 분석 가능한 Down Step 중 실제 최저 RPM의 대표 겉보기 점도. | H15: 고전단 이력 후 가장 낮은 하강 전단의 겉보기 점도. | I15: 전단 이력 후 저전단 저항. | J15: 잔류 저항 큼. | K15: 잔류 저항 작음. | L15: Up 최저 RPM과 다르면 그 RPM을 그대로 쓰고 비고에 불일치를 남긴다. 점도 회복률의 분모로 직접 나누지 않는다. | M15: 60초 회전 Step·후반 10초·Torque 10–95% 유효점만 사용. 미충족 시 공란(대체값 없음). | N15: RSD: GOOD ≤10, REVIEW ≤20
B16: T1 Lot 동일성 핵심 | C16: D_RHO25 | D16: CORE / 합격성 O | E16: 25 °C 탈포 젤 겉보기 밀도 ρ25 | F16: g/mL | G16: 독립 충전별 ρ = (m충전 − m공용기) / V교정(시험온도 물 교정 부피). 밀도계 직독값이 있으면 직독값을 쓰고 질량식과 교차확인. | H16: 젤 단위 부피당 질량. 수지·가소제 대 실리카 등 충전재의 배합비와 잔류 기포량이 합쳐진 값. | I16: 원심 중 젤이 혈청층과 혈구·혈병층 사이 어느 높이에 정착하는지를 정하는 1차 인자(부력 평형 위치). | J16: 충전재 과량·가소제 부족·계량 오차 가능. 장벽이 혈구층 쪽으로 낮게 형성되거나 상승 이동이 늦어질 수 있음. | K16: 기포 혼입·충전재 부족 가능. 장벽이 혈청층 쪽으로 뜨거나 혈청 중 젤 파편 위험. | L16: 밀도는 '어디에 정착하는가'만 말하며, '제때 이동·정착·재겔화하는가'는 유변 지표가 담당. DVNext CSV의 Density 열은 장비 입력 설정값이므로 사용하지 않음. 온도 보정 없음. | M16: 시험온도 25±0.5 °C, 탈포·충전·상면 정리 조건 고정, 독립 재충전 ≥3회. 소량 중량법은 기준법 비교로 적격화된 경우만. | N16: SD: GOOD ≤0.002, REVIEW ≤0.005
... B71: DQ 데이터 품질 | C71: B_REC_VALID | D71: DATA_QUALITY / 진단(제외) | E71: 회복 구간 유효 데이터 비율 | F71: % | G71: Interval 3 점 중 Torque 10–95% 비율. | H71: 회복 곡선의 정량 가능 범위. | I71: — | J71: 정량 범위 넓음. | K71: 저전단 조건 재설계 필요. | L71: — | M71: — | N71: —

Sheet A_Replicates
B1: Lot_QC_Summary | C1: QC_Dictionary | D1: A_Replicates | E1: B_Replicates | F1: Density_Replicates | G1: A_Replicates_INCL | H1: A_Replicates_EXC | I1: Metric_Statistics | J1: A_Step_Replicates | K1: A_Step_Statistics | L1: Replicate_Flags | M1: Traceability
B2: A_Replicates — STRICT 채널 반복별 QC 지표 원값
B3: STRICT: 60 s hold·Torque 10–95% 기준 값입니다. Inclusive 값은 A_Replicates_INCL, 예외 사용 내역은 A_Replicates_EXC·Replicate_Flags 참조.
B4: POLICY INCLUSIVE — accepted holds 30,45,60 s, 범위 밖 Torque 점 inclusive 포함. EXCEPTION·CENSORED 값은 표준 60 s Lot 통계·추세·규격 설정에 혼용 금지
B5: lot | C5: repeat | D5: file | E5: test_start | F5: route | G5: data_qc | H5: A_TAU_L_UP | I5: A_TAU_M_UP | J5: A_TAU_H_UP | K5: A_SSI_FIELD_0P2_2 | L5: A_SSI_QC_0P5_5 | M5: A_DU_L | N5: A_DU_M | O5: A_HYS_REL | P5: A_BRK_PEAK | Q5: A_HB_TAUY_UP | R5: A_HB_K_UP | S5: A_HB_N_UP | T5: A_HB_R2_UP | U5: A_HB_R2_DN | V5: A_HB_TAUY_DN | W5: A_HB_K_DN | X5: A_HB_N_DN | Y5: A_HB_TAUY_RATIO | Z5: A_HDI | AA5: A_OVS_L | AB5: A_HB_GRANGE | AC5: A_ETA_MIN_UP | AD5: A_ETA_HIGH | AE5: A_ETA_LOW_DN | AF5: A_STATIC_YIELD_APPROX_UP | AG5: A_POST_SHEAR_STARTUP_STRESS | AH5: A_POST_SHEAR_STRESS_RETENTION | AI5: A_ETA_RECOVERY_LOW | AJ5: A_HYS_AREA_SIGNED | AK5: A_HYS_AREA_ABS | AL5: A_HB_K_RATIO | AM5: A_HB_N_DIFF | AN5: A_HB_TAUY_UP_COMMON | AO5: A_HB_K_UP_COMMON | AP5: A_HB_N_UP_COMMON | AQ5: A_HB_R2_UP_COMMON | AR5: A_HB_TAUY_DN_COMMON | AS5: A_HB_K_DN_COMMON | AT5: A_HB_N_DN_COMMON | AU5: A_HB_R2_DN_COMMON | AV5: A_HB_TAUY_RATIO_COMMON | AW5: A_STARTUP_PLATEAU_UP | AX5: A_POST_SHEAR_PLATEAU | AY5: A_PLATEAU_RETENTION | AZ5: A_TQ_L | BA5: A_RES_L | BB5: A_DUL_FLOOR | BC5: A_EQ_DRIFT_MAX | BD5: A_TEMP_MEAN | BE5: A_TEMP_SPAN | BF5: A_N_QUANT | BG5: A_TAU_L_UP__include_in_lot_stats | BH5: A_TAU_L_UP__stat_value | BI5: A_TAU_L_UP__lot_exclusion_reason | BJ5: A_TAU_M_UP__include_in_lot_stats | BK5: A_TAU_M_UP__stat_value | BL5: A_TAU_M_UP__lot_exclusion_reason | BM5: A_TAU_H_UP__include_in_lot_stats | BN5: A_TAU_H_UP__stat_value | BO5: A_TAU_H_UP__lot_exclusion_reason | BP5: A_SSI_FIELD_0P2_2__include_in_lot_stats | BQ5: A_SSI_FIELD_0P2_2__stat_value | BR5: A_SSI_FIELD_0P2_2__lot_exclusion_reason | BS5: A_SSI_QC_0P5_5__include_in_lot_stats | BT5: A_SSI_QC_0P5_5__stat_value | BU5: A_SSI_QC_0P5_5__lot_exclusion_reason | BV5: A_DU_L__include_in_lot_stats | BW5: A_DU_L__stat_value | BX5: A_DU_L__lot_exclusion_reason | BY5: A_DU_M__include_in_lot_stats | BZ5: A_DU_M__stat_value | CA5: A_DU_M__lot_exclusion_reason | CB5: A_HYS_REL__include_in_lot_stats | CC5: A_HYS_REL__stat_value | CD5: A_HYS_REL__lot_exclusion_reason | CE5: A_BRK_PEAK__include_in_lot_stats | CF5: A_BRK_PEAK__stat_value | CG5: A_BRK_PEAK__lot_exclusion_reason | CH5: A_HB_TAUY_UP__include_in_lot_stats | CI5: A_HB_TAUY_UP__stat_value | CJ5: A_HB_TAUY_UP__lot_exclusion_reason | CK5: A_HB_K_UP__include_in_lot_stats | CL5: A_HB_K_UP__stat_value | CM5: A_HB_K_UP__lot_exclusion_reason | CN5: A_HB_N_UP__include_in_lot_stats | CO5: A_HB_N_UP__stat_value | CP5: A_HB_N_UP__lot_exclusion_reason | CQ5: A_HB_R2_UP__include_in_lot_stats | CR5: A_HB_R2_UP__stat_value | CS5: A_HB_R2_UP__lot_exclusion_reason | CT5: A_HB_R2_DN__include_in_lot_stats | CU5: A_HB_R2_DN__stat_value | CV5: A_HB_R2_DN__lot_exclusion_reason | CW5: A_HB_TAUY_DN__include_in_lot_stats | CX5: A_HB_TAUY_DN__stat_value | CY5: A_HB_TAUY_DN__lot_exclusion_reason | CZ5: A_HB_K_DN__include_in_lot_stats | DA5: A_HB_K_DN__stat_value | DB5: A_HB_K_DN__lot_exclusion_reason | DC5: A_HB_N_DN__include_in_lot_stats | DD5: A_HB_N_DN__stat_value | DE5: A_HB_N_DN__lot_exclusion_reason | DF5: A_HB_TAUY_RATIO__include_in_lot_stats | DG5: A_HB_TAUY_RATIO__stat_value | DH5: A_HB_TAUY_RATIO__lot_exclusion_reason | DI5: A_HDI__include_in_lot_stats | DJ5: A_HDI__stat_value | DK5: A_HDI__lot_exclusion_reason | DL5: A_OVS_L__include_in_lot_stats | DM5: A_OVS_L__stat_value | DN5: A_OVS_L__lot_exclusion_reason | DO5: A_HB_GRANGE__include_in_lot_stats | DP5: A_HB_GRANGE__stat_value | DQ5: A_HB_GRANGE__lot_exclusion_reason | DR5: A_ETA_MIN_UP__include_in_lot_stats | DS5: A_ETA_MIN_UP__stat_value | DT5: A_ETA_MIN_UP__lot_exclusion_reason | DU5: A_ETA_HIGH__include_in_lot_stats | DV5: A_ETA_HIGH__stat_value | DW5: A_ETA_HIGH__lot_exclusion_reason | DX5: A_ETA_LOW_DN__include_in_lot_stats | DY5: A_ETA_LOW_DN__stat_value | DZ5: A_ETA_LOW_DN__lot_exclusion_reason | EA5: A_STATIC_YIELD_APPROX_UP__include_in_lot_stats | EB5: A_STATIC_YIELD_APPROX_UP__stat_value | EC5: A_STATIC_YIELD_APPROX_UP__lot_exclusion_reason | ED5: A_POST_SHEAR_STARTUP_STRESS__include_in_lot_stats | EE5: A_POST_SHEAR_STARTUP_STRESS__stat_value | EF5: A_POST_SHEAR_STARTUP_STRESS__lot_exclusion_reason | EG5: A_POST_SHEAR_STRESS_RETENTION__include_in_lot_stats | EH5: A_POST_SHEAR_STRESS_RETENTION__stat_value | EI5: A_POST_SHEAR_STRESS_RETENTION__lot_exclusion_reason | EJ5: A_ETA_RECOVERY_LOW__include_in_lot_stats | EK5: A_ETA_RECOVERY_LOW__stat_value | EL5: A_ETA_RECOVERY_LOW__lot_exclusion_reason | EM5: A_HYS_AREA_SIGNED__include_in_lot_stats | EN5: A_HYS_AREA_SIGNED__stat_value | EO5: A_HYS_AREA_SIGNED__lot_exclusion_reason | EP5: A_HYS_AREA_ABS__include_in_lot_stats | EQ5: A_HYS_AREA_ABS__stat_value | ER5: A_HYS_AREA_ABS__lot_exclusion_reason | ES5: A_HB_K_RATIO__include_in_lot_stats | ET5: A_HB_K_RATIO__stat_value | EU5: A_HB_K_RATIO__lot_exclusion_reason | EV5: A_HB_N_DIFF__include_in_lot_stats | EW5: A_HB_N_DIFF__stat_value | EX5: A_HB_N_DIFF__lot_exclusion_reason | EY5: A_HB_TAUY_UP_COMMON__include_in_lot_stats | EZ5: A_HB_TAUY_UP_COMMON__stat_value | FA5: A_HB_TAUY_UP_COMMON__lot_exclusion_reason | FB5: A_HB_K_UP_COMMON__include_in_lot_stats | FC5: A_HB_K_UP_COMMON__stat_value | FD5: A_HB_K_UP_COMMON__lot_exclusion_reason | FE5: A_HB_N_UP_COMMON__include_in_lot_stats | FF5: A_HB_N_UP_COMMON__stat_value | FG5: A_HB_N_UP_COMMON__lot_exclusion_reason | FH5: A_HB_R2_UP_COMMON__include_in_lot_stats | FI5: A_HB_R2_UP_COMMON__stat_value | FJ5: A_HB_R2_UP_COMMON__lot_exclusion_reason | FK5: A_HB_TAUY_DN_COMMON__include_in_lot_stats | FL5: A_HB_TAUY_DN_COMMON__stat_value | FM5: A_HB_TAUY_DN_COMMON__lot_exclusion_reason | FN5: A_HB_K_DN_COMMON__include_in_lot_stats | FO5: A_HB_K_DN_COMMON__stat_value | FP5: A_HB_K_DN_COMMON__lot_exclusion_reason | FQ5: A_HB_N_DN_COMMON__include_in_lot_stats | FR5: A_HB_N_DN_COMMON__stat_value | FS5: A_HB_N_DN_COMMON__lot_exclusion_reason | FT5: A_HB_R2_DN_COMMON__include_in_lot_stats | FU5: A_HB_R2_DN_COMMON__stat_value | FV5: A_HB_R2_DN_COMMON__lot_exclusion_reason | FW5: A_HB_TAUY_RATIO_COMMON__include_in_lot_stats | FX5: A_HB_TAUY_RATIO_COMMON__stat_value | FY5: A_HB_TAUY_RATIO_COMMON__lot_exclusion_reason | FZ5: A_STARTUP_PLATEAU_UP__include_in_lot_stats | GA5: A_STARTUP_PLATEAU_UP__stat_value | GB5: A_STARTUP_PLATEAU_UP__lot_exclusion_reason | GC5: A_POST_SHEAR_PLATEAU__include_in_lot_stats | GD5: A_POST_SHEAR_PLATEAU__stat_value | GE5: A_POST_SHEAR_PLATEAU__lot_exclusion_reason | GF5: A_PLATEAU_RETENTION__include_in_lot_stats | GG5: A_PLATEAU_RETENTION__stat_value | GH5: A_PLATEAU_RETENTION__lot_exclusion_reason | GI5: A_TQ_L__include_in_lot_stats | GJ5: A_TQ_L__stat_value | GK5: A_TQ_L__lot_exclusion_reason | GL5: A_RES_L__include_in_lot_stats | GM5: A_RES_L__stat_value | GN5: A_RES_L__lot_exclusion_reason | GO5: A_DUL_FLOOR__include_in_lot_stats | GP5: A_DUL_FLOOR__stat_value | GQ5: A_DUL_FLOOR__lot_exclusion_reason | GR5: A_EQ_DRIFT_MAX__include_in_lot_stats | GS5: A_EQ_DRIFT_MAX__stat_value | GT5: A_EQ_DRIFT_MAX__lot_exclusion_reason | GU5: A_TEMP_MEAN__include_in_lot_stats | GV5: A_TEMP_MEAN__stat_value | GW5: A_TEMP_MEAN__lot_exclusion_reason | GX5: A_TEMP_SPAN__include_in_lot_stats | GY5: A_TEMP_SPAN__stat_value | GZ5: A_TEMP_SPAN__lot_exclusion_reason | HA5: A_N_QUANT__include_in_lot_stats | HB5: A_N_QUANT__stat_value | HC5: A_N_QUANT__lot_exclusion_reason | HD5: A_SSI_FIELD_0P2_2_value | HE5: A_SSI_FIELD_0P2_2_num_rpm | HF5: A_SSI_FIELD_0P2_2_den_rpm | HG5: A_SSI_FIELD_0P2_2_num_step | HH5: A_SSI_FIELD_0P2_2_den_step | HI5: A_SSI_FIELD_0P2_2_value_class | HJ5: A_SSI_QC_0P5_5_value | HK5: A_SSI_QC_0P5_5_num_rpm | HL5: A_SSI_QC_0P5_5_den_rpm | HM5: A_SSI_QC_0P5_5_num_step | HN5: A_SSI_QC_0P5_5_den_step | HO5: A_SSI_QC_0P5_5_value_class | HP5: A_TAU_H_UP_rpm | HQ5: A_TAU_H_UP_step | HR5: A_ETA_HIGH_rpm | HS5: A_ETA_HIGH_step | HT5: temp_control
B6: SYN | C6: 01 | D6: HT-SYN-01.csv | F6: INCLUSIVE | G6: VALID | H6: 200 | I6: 200 | J6: 200 | K6: 10 | L6: 10 | P6: 0 | Q6: 200 | R6: 2.8097743e-07 | S6: 0.050002953 | AA6: 0 | AB6: 25 | AC6: 500000 | AD6: 20000 | AF6: 200 | AZ6: 20 | BA6: 0.5 | BB6: 50 | BC6: 3.396219e-14 | BD6: 25 | BE6: 0 | BF6: 10 | BG6: 1 | BH6: 200 | BJ6: 1 | BK6: 200 | BM6: 1 | BN6: 200 | BP6: 1 | BQ6: 10 | BS6: 1 | BT6: 10 | BV6: 0 | BX6: non-finite | BY6: 0 | CA6: non-finite | CB6: 0 | CD6: non-finite | CE6: 1 | CF6: 0 | CH6: 1 | CI6: 200 | CK6: 1 | CL6: 2.8097743e-07 | CN6: 1 | CO6: 0.050002953 | CQ6: 0 | CS6: non-finite | CT6: 0 | CV6: non-finite | CW6: 0 | CY6: non-finite | CZ6: 0 | DB6: non-finite | DC6: 0 | DE6: non-finite | DF6: 0 | DH6: non-finite | DI6: 0 | DK6: non-finite | DL6: 1 | DM6: 0 | DO6: 1 | DP6: 25 | DR6: 1 | DS6: 500000 | DU6: 1 | DV6: 20000 | DX6: 0 | DZ6: non-finite | EA6: 1 | EB6: 200 | ED6: 0 | EF6: non-finite | EG6: 0 | EI6: non-finite | EJ6: 0 | EL6: non-finite | EM6: 0 | EO6: non-finite | EP6: 0 | ER6: non-finite | ES6: 0 | EU6: non-finite | EV6: 0 | EX6: non-finite | EY6: 0 | FA6: non-finite | FB6: 0 | FD6: non-finite | FE6: 0 | FG6: non-finite | FH6: 0 | FJ6: non-finite | FK6: 0 | FM6: non-finite | FN6: 0 | FP6: non-finite | FQ6: 0 | FS6: non-finite | FT6: 0 | FV6: non-finite | FW6: 0 | FY6: non-finite | FZ6: 0 | GB6: non-finite | GC6: 0 | GE6: non-finite | GF6: 0 | GH6: non-finite | GI6: 1 | GJ6: 20 | GL6: 1 | GM6: 0.5 | GO6: 1 | GP6: 50 | GR6: 1 | GS6: 3.396219e-14 | GU6: 1 | GV6: 25 | GX6: 1 | GY6: 0 | HA6: 1 | HB6: 10 | HD6: 10 | HE6: 0.2 | HF6: 2 | HG6: S2 | HH6: S8 | HI6: strict 정량값 | HJ6: 10 | HK6: 0.5 | HL6: 5 | HM6: S4 | HN6: S11 | HO6: strict 정량값 | HP6: 5 | HQ6: S11 | HR6: 5 | HS6: S11 | HT6: No

Sheet B_Replicates
B1: Lot_QC_Summary | C1: QC_Dictionary | D1: A_Replicates | E1: B_Replicates | F1: Density_Replicates | G1: A_Replicates_INCL | H1: A_Replicates_EXC | I1: Metric_Statistics | J1: A_Step_Replicates | K1: A_Step_Statistics | L1: Replicate_Flags | M1: Traceability
B2: B_Replicates — 반복별 QC 지표 원값
B3: Python 공식 계산값(숫자형). 공란 = 유효 조건 미충족(사유는 Replicate_Flags). 이 시트 값을 수정하면 통계가 자동 재계산됩니다.
B4: POLICY INCLUSIVE — accepted holds 30,45,60 s, 범위 밖 Torque 점 inclusive 포함. EXCEPTION·CENSORED 값은 표준 60 s Lot 통계·추세·규격 설정에 혼용 금지
B5: lot | C5: repeat | D5: file | E5: test_start | F5: route | G5: data_qc | H5: B_ETA_BASE | I5: B_BRK_DECAY | J5: B_R60 | K5: B_R300 | L5: B_T90 | M5: B_ETA_BRK | N5: B_R10 | O5: B_R900 | P5: B_TQ_BASE | Q5: B_REC_FLOOR | R5: B_REC_VALID | S5: B_ETA_BASE__include_in_lot_stats | T5: B_ETA_BASE__stat_value | U5: B_ETA_BASE__lot_exclusion_reason | V5: B_BRK_DECAY__include_in_lot_stats | W5: B_BRK_DECAY__stat_value | X5: B_BRK_DECAY__lot_exclusion_reason | Y5: B_R60__include_in_lot_stats | Z5: B_R60__stat_value | AA5: B_R60__lot_exclusion_reason | AB5: B_R300__include_in_lot_stats | AC5: B_R300__stat_value | AD5: B_R300__lot_exclusion_reason | AE5: B_T90__include_in_lot_stats | AF5: B_T90__stat_value | AG5: B_T90__lot_exclusion_reason | AH5: B_ETA_BRK__include_in_lot_stats | AI5: B_ETA_BRK__stat_value | AJ5: B_ETA_BRK__lot_exclusion_reason | AK5: B_R10__include_in_lot_stats | AL5: B_R10__stat_value | AM5: B_R10__lot_exclusion_reason | AN5: B_R900__include_in_lot_stats | AO5: B_R900__stat_value | AP5: B_R900__lot_exclusion_reason | AQ5: B_TQ_BASE__include_in_lot_stats | AR5: B_TQ_BASE__stat_value | AS5: B_TQ_BASE__lot_exclusion_reason | AT5: B_REC_FLOOR__include_in_lot_stats | AU5: B_REC_FLOOR__stat_value | AV5: B_REC_FLOOR__lot_exclusion_reason | AW5: B_REC_VALID__include_in_lot_stats | AX5: B_REC_VALID__stat_value | AY5: B_REC_VALID__lot_exclusion_reason | AZ5: temp_control

Sheet Density_Replicates
B1: Lot_QC_Summary | C1: QC_Dictionary | D1: A_Replicates | E1: B_Replicates | F1: Density_Replicates | G1: A_Replicates_INCL | H1: A_Replicates_EXC | I1: Metric_Statistics | J1: A_Step_Replicates | K1: A_Step_Statistics | L1: Replicate_Flags | M1: Traceability
B2: Density_Replicates — 반복별 QC 지표 원값
B3: Python 공식 계산값(숫자형). 공란 = 유효 조건 미충족(사유는 Replicate_Flags). 이 시트 값을 수정하면 통계가 자동 재계산됩니다.
B4: POLICY INCLUSIVE — accepted holds 30,45,60 s, 범위 밖 Torque 점 inclusive 포함. EXCEPTION·CENSORED 값은 표준 60 s Lot 통계·추세·규격 설정에 혼용 금지
B5: lot | C5: repeat | D5: file | E5: test_start | F5: route | G5: data_qc | H5: D_RHO25 | I5: D_TEMP | J5: D_RHO25__include_in_lot_stats | K5: D_RHO25__stat_value | L5: D_RHO25__lot_exclusion_reason | M5: D_TEMP__include_in_lot_stats | N5: D_TEMP__stat_value | O5: D_TEMP__lot_exclusion_reason | P5: density_method | Q5: operator | R5: mass_empty_g | S5: mass_filled_g | T5: volume_mL | U5: density_direct | V5: density_calc | W5: note

Sheet A_Replicates_INCL
B1: Lot_QC_Summary | C1: QC_Dictionary | D1: A_Replicates | E1: B_Replicates | F1: Density_Replicates | G1: A_Replicates_INCL | H1: A_Replicates_EXC | I1: Metric_Statistics | J1: A_Step_Replicates | K1: A_Step_Statistics | L1: Replicate_Flags | M1: Traceability
B2: A_Replicates_INCL — INCLUSIVE 채널 전체 반복값(감사용)
B3: 정책 허용 hold·범위 밖 참고값을 포함한 inclusive 값입니다. CENSORED여도 셀을 비우지 않고, 오른쪽 값 구분 열에 출처를 남깁니다. Metric_Statistics의 inclusive 평균은 정책이 허용한 값 구분만 집계합니다.
B4: POLICY INCLUSIVE — accepted holds 30,45,60 s, 범위 밖 Torque 점 inclusive 포함. EXCEPTION·CENSORED 값은 표준 60 s Lot 통계·추세·규격 설정에 혼용 금지
B5: lot | C5: repeat | D5: file | E5: test_start | F5: route | G5: data_qc | H5: A_TAU_L_UP | I5: A_TAU_M_UP | J5: A_TAU_H_UP | K5: A_SSI_FIELD_0P2_2 | L5: A_SSI_QC_0P5_5 | M5: A_DU_L | N5: A_DU_M | O5: A_HYS_REL | P5: A_BRK_PEAK | Q5: A_HB_TAUY_UP | R5: A_HB_K_UP | S5: A_HB_N_UP | T5: A_HB_R2_UP | U5: A_HB_R2_DN | V5: A_HB_TAUY_DN | W5: A_HB_K_DN | X5: A_HB_N_DN | Y5: A_HB_TAUY_RATIO | Z5: A_HDI | AA5: A_OVS_L | AB5: A_HB_GRANGE | AC5: A_ETA_MIN_UP | AD5: A_ETA_HIGH | AE5: A_ETA_LOW_DN | AF5: A_STATIC_YIELD_APPROX_UP | AG5: A_POST_SHEAR_STARTUP_STRESS | AH5: A_POST_SHEAR_STRESS_RETENTION | AI5: A_ETA_RECOVERY_LOW | AJ5: A_HYS_AREA_SIGNED | AK5: A_HYS_AREA_ABS | AL5: A_HB_K_RATIO | AM5: A_HB_N_DIFF | AN5: A_HB_TAUY_UP_COMMON | AO5: A_HB_K_UP_COMMON | AP5: A_HB_N_UP_COMMON | AQ5: A_HB_R2_UP_COMMON | AR5: A_HB_TAUY_DN_COMMON | AS5: A_HB_K_DN_COMMON | AT5: A_HB_N_DN_COMMON | AU5: A_HB_R2_DN_COMMON | AV5: A_HB_TAUY_RATIO_COMMON | AW5: A_STARTUP_PLATEAU_UP | AX5: A_POST_SHEAR_PLATEAU | AY5: A_PLATEAU_RETENTION | AZ5: A_TQ_L | BA5: A_RES_L | BB5: A_DUL_FLOOR | BC5: A_EQ_DRIFT_MAX | BD5: A_TEMP_MEAN | BE5: A_TEMP_SPAN | BF5: A_N_QUANT | BG5: A_TAU_L_UP__include_in_lot_stats | BH5: A_TAU_L_UP__stat_value | BI5: A_TAU_L_UP__lot_exclusion_reason | BJ5: A_TAU_M_UP__include_in_lot_stats | BK5: A_TAU_M_UP__stat_value | BL5: A_TAU_M_UP__lot_exclusion_reason | BM5: A_TAU_H_UP__include_in_lot_stats | BN5: A_TAU_H_UP__stat_value | BO5: A_TAU_H_UP__lot_exclusion_reason | BP5: A_SSI_FIELD_0P2_2__include_in_lot_stats | BQ5: A_SSI_FIELD_0P2_2__stat_value | BR5: A_SSI_FIELD_0P2_2__lot_exclusion_reason | BS5: A_SSI_QC_0P5_5__include_in_lot_stats | BT5: A_SSI_QC_0P5_5__stat_value | BU5: A_SSI_QC_0P5_5__lot_exclusion_reason | BV5: A_DU_L__include_in_lot_stats | BW5: A_DU_L__stat_value | BX5: A_DU_L__lot_exclusion_reason | BY5: A_DU_M__include_in_lot_stats | BZ5: A_DU_M__stat_value | CA5: A_DU_M__lot_exclusion_reason | CB5: A_HYS_REL__include_in_lot_stats | CC5: A_HYS_REL__stat_value | CD5: A_HYS_REL__lot_exclusion_reason | CE5: A_BRK_PEAK__include_in_lot_stats | CF5: A_BRK_PEAK__stat_value | CG5: A_BRK_PEAK__lot_exclusion_reason | CH5: A_HB_TAUY_UP__include_in_lot_stats | CI5: A_HB_TAUY_UP__stat_value | CJ5: A_HB_TAUY_UP__lot_exclusion_reason | CK5: A_HB_K_UP__include_in_lot_stats | CL5: A_HB_K_UP__stat_value | CM5: A_HB_K_UP__lot_exclusion_reason | CN5: A_HB_N_UP__include_in_lot_stats | CO5: A_HB_N_UP__stat_value | CP5: A_HB_N_UP__lot_exclusion_reason | CQ5: A_HB_R2_UP__include_in_lot_stats | CR5: A_HB_R2_UP__stat_value | CS5: A_HB_R2_UP__lot_exclusion_reason | CT5: A_HB_R2_DN__include_in_lot_stats | CU5: A_HB_R2_DN__stat_value | CV5: A_HB_R2_DN__lot_exclusion_reason | CW5: A_HB_TAUY_DN__include_in_lot_stats | CX5: A_HB_TAUY_DN__stat_value | CY5: A_HB_TAUY_DN__lot_exclusion_reason | CZ5: A_HB_K_DN__include_in_lot_stats | DA5: A_HB_K_DN__stat_value | DB5: A_HB_K_DN__lot_exclusion_reason | DC5: A_HB_N_DN__include_in_lot_stats | DD5: A_HB_N_DN__stat_value | DE5: A_HB_N_DN__lot_exclusion_reason | DF5: A_HB_TAUY_RATIO__include_in_lot_stats | DG5: A_HB_TAUY_RATIO__stat_value | DH5: A_HB_TAUY_RATIO__lot_exclusion_reason | DI5: A_HDI__include_in_lot_stats | DJ5: A_HDI__stat_value | DK5: A_HDI__lot_exclusion_reason | DL5: A_OVS_L__include_in_lot_stats | DM5: A_OVS_L__stat_value | DN5: A_OVS_L__lot_exclusion_reason | DO5: A_HB_GRANGE__include_in_lot_stats | DP5: A_HB_GRANGE__stat_value | DQ5: A_HB_GRANGE__lot_exclusion_reason | DR5: A_ETA_MIN_UP__include_in_lot_stats | DS5: A_ETA_MIN_UP__stat_value | DT5: A_ETA_MIN_UP__lot_exclusion_reason | DU5: A_ETA_HIGH__include_in_lot_stats | DV5: A_ETA_HIGH__stat_value | DW5: A_ETA_HIGH__lot_exclusion_reason | DX5: A_ETA_LOW_DN__include_in_lot_stats | DY5: A_ETA_LOW_DN__stat_value | DZ5: A_ETA_LOW_DN__lot_exclusion_reason | EA5: A_STATIC_YIELD_APPROX_UP__include_in_lot_stats | EB5: A_STATIC_YIELD_APPROX_UP__stat_value | EC5: A_STATIC_YIELD_APPROX_UP__lot_exclusion_reason | ED5: A_POST_SHEAR_STARTUP_STRESS__include_in_lot_stats | EE5: A_POST_SHEAR_STARTUP_STRESS__stat_value | EF5: A_POST_SHEAR_STARTUP_STRESS__lot_exclusion_reason | EG5: A_POST_SHEAR_STRESS_RETENTION__include_in_lot_stats | EH5: A_POST_SHEAR_STRESS_RETENTION__stat_value | EI5: A_POST_SHEAR_STRESS_RETENTION__lot_exclusion_reason | EJ5: A_ETA_RECOVERY_LOW__include_in_lot_stats | EK5: A_ETA_RECOVERY_LOW__stat_value | EL5: A_ETA_RECOVERY_LOW__lot_exclusion_reason | EM5: A_HYS_AREA_SIGNED__include_in_lot_stats | EN5: A_HYS_AREA_SIGNED__stat_value | EO5: A_HYS_AREA_SIGNED__lot_exclusion_reason | EP5: A_HYS_AREA_ABS__include_in_lot_stats | EQ5: A_HYS_AREA_ABS__stat_value | ER5: A_HYS_AREA_ABS__lot_exclusion_reason | ES5: A_HB_K_RATIO__include_in_lot_stats | ET5: A_HB_K_RATIO__stat_value | EU5: A_HB_K_RATIO__lot_exclusion_reason | EV5: A_HB_N_DIFF__include_in_lot_stats | EW5: A_HB_N_DIFF__stat_value | EX5: A_HB_N_DIFF__lot_exclusion_reason | EY5: A_HB_TAUY_UP_COMMON__include_in_lot_stats | EZ5: A_HB_TAUY_UP_COMMON__stat_value | FA5: A_HB_TAUY_UP_COMMON__lot_exclusion_reason | FB5: A_HB_K_UP_COMMON__include_in_lot_stats | FC5: A_HB_K_UP_COMMON__stat_value | FD5: A_HB_K_UP_COMMON__lot_exclusion_reason | FE5: A_HB_N_UP_COMMON__include_in_lot_stats | FF5: A_HB_N_UP_COMMON__stat_value | FG5: A_HB_N_UP_COMMON__lot_exclusion_reason | FH5: A_HB_R2_UP_COMMON__include_in_lot_stats | FI5: A_HB_R2_UP_COMMON__stat_value | FJ5: A_HB_R2_UP_COMMON__lot_exclusion_reason | FK5: A_HB_TAUY_DN_COMMON__include_in_lot_stats | FL5: A_HB_TAUY_DN_COMMON__stat_value | FM5: A_HB_TAUY_DN_COMMON__lot_exclusion_reason | FN5: A_HB_K_DN_COMMON__include_in_lot_stats | FO5: A_HB_K_DN_COMMON__stat_value | FP5: A_HB_K_DN_COMMON__lot_exclusion_reason | FQ5: A_HB_N_DN_COMMON__include_in_lot_stats | FR5: A_HB_N_DN_COMMON__stat_value | FS5: A_HB_N_DN_COMMON__lot_exclusion_reason | FT5: A_HB_R2_DN_COMMON__include_in_lot_stats | FU5: A_HB_R2_DN_COMMON__stat_value | FV5: A_HB_R2_DN_COMMON__lot_exclusion_reason | FW5: A_HB_TAUY_RATIO_COMMON__include_in_lot_stats | FX5: A_HB_TAUY_RATIO_COMMON__stat_value | FY5: A_HB_TAUY_RATIO_COMMON__lot_exclusion_reason | FZ5: A_STARTUP_PLATEAU_UP__include_in_lot_stats | GA5: A_STARTUP_PLATEAU_UP__stat_value | GB5: A_STARTUP_PLATEAU_UP__lot_exclusion_reason | GC5: A_POST_SHEAR_PLATEAU__include_in_lot_stats | GD5: A_POST_SHEAR_PLATEAU__stat_value | GE5: A_POST_SHEAR_PLATEAU__lot_exclusion_reason | GF5: A_PLATEAU_RETENTION__include_in_lot_stats | GG5: A_PLATEAU_RETENTION__stat_value | GH5: A_PLATEAU_RETENTION__lot_exclusion_reason | GI5: A_TQ_L__include_in_lot_stats | GJ5: A_TQ_L__stat_value | GK5: A_TQ_L__lot_exclusion_reason | GL5: A_RES_L__include_in_lot_stats | GM5: A_RES_L__stat_value | GN5: A_RES_L__lot_exclusion_reason | GO5: A_DUL_FLOOR__include_in_lot_stats | GP5: A_DUL_FLOOR__stat_value | GQ5: A_DUL_FLOOR__lot_exclusion_reason | GR5: A_EQ_DRIFT_MAX__include_in_lot_stats | GS5: A_EQ_DRIFT_MAX__stat_value | GT5: A_EQ_DRIFT_MAX__lot_exclusion_reason | GU5: A_TEMP_MEAN__include_in_lot_stats | GV5: A_TEMP_MEAN__stat_value | GW5: A_TEMP_MEAN__lot_exclusion_reason | GX5: A_TEMP_SPAN__include_in_lot_stats | GY5: A_TEMP_SPAN__stat_value | GZ5: A_TEMP_SPAN__lot_exclusion_reason | HA5: A_N_QUANT__include_in_lot_stats | HB5: A_N_QUANT__stat_value | HC5: A_N_QUANT__lot_exclusion_reason | HD5: A_SSI_FIELD_0P2_2_value | HE5: A_SSI_FIELD_0P2_2_num_rpm | HF5: A_SSI_FIELD_0P2_2_den_rpm | HG5: A_SSI_FIELD_0P2_2_num_step | HH5: A_SSI_FIELD_0P2_2_den_step | HI5: A_SSI_FIELD_0P2_2_value_class | HJ5: A_SSI_QC_0P5_5_value | HK5: A_SSI_QC_0P5_5_num_rpm | HL5: A_SSI_QC_0P5_5_den_rpm | HM5: A_SSI_QC_0P5_5_num_step | HN5: A_SSI_QC_0P5_5_den_step | HO5: A_SSI_QC_0P5_5_value_class | HP5: A_TAU_H_UP_rpm | HQ5: A_TAU_H_UP_step | HR5: A_ETA_HIGH_rpm | HS5: A_ETA_HIGH_step | HT5: A_TAU_L_UP_class | HU5: A_TAU_M_UP_class | HV5: A_TAU_H_UP_class | HW5: A_SSI_FIELD_0P2_2_class | HX5: A_SSI_QC_0P5_5_class | HY5: A_DU_L_class | HZ5: A_DU_M_class | IA5: A_HYS_REL_class | IB5: A_BRK_PEAK_class | IC5: A_HB_TAUY_UP_class | ID5: A_HB_K_UP_class | IE5: A_HB_N_UP_class | IF5: A_HB_R2_UP_class | IG5: A_HB_R2_DN_class | IH5: A_HB_TAUY_DN_class | II5: A_HB_K_DN_class | IJ5: A_HB_N_DN_class | IK5: A_HB_TAUY_RATIO_class | IL5: A_HDI_class | IM5: A_OVS_L_class | IN5: A_HB_GRANGE_class | IO5: A_ETA_MIN_UP_class | IP5: A_ETA_HIGH_class | IQ5: A_ETA_LOW_DN_class | IR5: A_STATIC_YIELD_APPROX_UP_class | IS5: A_POST_SHEAR_STARTUP_STRESS_class | IT5: A_POST_SHEAR_STRESS_RETENTION_class | IU5: A_ETA_RECOVERY_LOW_class | IV5: A_HYS_AREA_SIGNED_class | IW5: A_HYS_AREA_ABS_class | IX5: A_HB_K_RATIO_class | IY5: A_HB_N_DIFF_class | IZ5: A_HB_TAUY_UP_COMMON_class | JA5: A_HB_K_UP_COMMON_class | JB5: A_HB_N_UP_COMMON_class | JC5: A_HB_R2_UP_COMMON_class | JD5: A_HB_TAUY_DN_COMMON_class | JE5: A_HB_K_DN_COMMON_class | JF5: A_HB_N_DN_COMMON_class | JG5: A_HB_R2_DN_COMMON_class | JH5: A_HB_TAUY_RATIO_COMMON_class | JI5: A_STARTUP_PLATEAU_UP_class | JJ5: A_POST_SHEAR_PLATEAU_class | JK5: A_PLATEAU_RETENTION_class | JL5: A_TQ_L_class | JM5: A_RES_L_class | JN5: A_DUL_FLOOR_class | JO5: A_EQ_DRIFT_MAX_class | JP5: A_TEMP_MEAN_class | JQ5: A_TEMP_SPAN_class | JR5: A_N_QUANT_class
B6: SYN | C6: 01 | D6: HT-SYN-01.csv | F6: INCLUSIVE | G6: VALID | H6: 200 | I6: 200 | J6: 200 | K6: 10 | L6: 10 | P6: 0 | Q6: 200 | R6: 2.8097743e-07 | S6: 0.050002953 | AA6: 0 | AB6: 25 | AC6: 500000 | AD6: 20000 | AF6: 200 | AZ6: 20 | BA6: 0.5 | BB6: 50 | BC6: 3.396219e-14 | BD6: 25 | BE6: 0 | BF6: 10 | BG6: 1 | BH6: 200 | BJ6: 1 | BK6: 200 | BM6: 1 | BN6: 200 | BP6: 1 | BQ6: 10 | BS6: 1 | BT6: 10 | BV6: 0 | BX6: non-finite | BY6: 0 | CA6: non-finite | CB6: 0 | CD6: non-finite | CE6: 1 | CF6: 0 | CH6: 1 | CI6: 200 | CK6: 1 | CL6: 2.8097743e-07 | CN6: 1 | CO6: 0.050002953 | CQ6: 0 | CS6: non-finite | CT6: 0 | CV6: non-finite | CW6: 0 | CY6: non-finite | CZ6: 0 | DB6: non-finite | DC6: 0 | DE6: non-finite | DF6: 0 | DH6: non-finite | DI6: 0 | DK6: non-finite | DL6: 1 | DM6: 0 | DO6: 1 | DP6: 25 | DR6: 1 | DS6: 500000 | DU6: 1 | DV6: 20000 | DX6: 0 | DZ6: non-finite | EA6: 1 | EB6: 200 | ED6: 0 | EF6: non-finite | EG6: 0 | EI6: non-finite | EJ6: 0 | EL6: non-finite | EM6: 0 | EO6: non-finite | EP6: 0 | ER6: non-finite | ES6: 0 | EU6: non-finite | EV6: 0 | EX6: non-finite | EY6: 0 | FA6: non-finite | FB6: 0 | FD6: non-finite | FE6: 0 | FG6: non-finite | FH6: 0 | FJ6: non-finite | FK6: 0 | FM6: non-finite | FN6: 0 | FP6: non-finite | FQ6: 0 | FS6: non-finite | FT6: 0 | FV6: non-finite | FW6: 0 | FY6: non-finite | FZ6: 0 | GB6: non-finite | GC6: 0 | GE6: non-finite | GF6: 0 | GH6: non-finite | GI6: 1 | GJ6: 20 | GL6: 1 | GM6: 0.5 | GO6: 1 | GP6: 50 | GR6: 1 | GS6: 3.396219e-14 | GU6: 1 | GV6: 25 | GX6: 1 | GY6: 0 | HA6: 1 | HB6: 10 | HD6: 10 | HE6: 0.2 | HF6: 2 | HG6: S2 | HH6: S8 | HI6: strict 정량값 | HJ6: 10 | HK6: 0.5 | HL6: 5 | HM6: S4 | HN6: S11 | HO6: strict 정량값 | HP6: 5 | HQ6: S11 | HR6: 5 | HS6: S11 | HT6: strict 정량값 | HU6: strict 정량값 | HV6: strict 정량값 | HW6: strict 정량값 | HX6: strict 정량값 | HY6: strict 정량값 | HZ6: strict 정량값 | IA6: NO VALUE | IB6: strict 정량값 | IC6: strict 정량값 | ID6: strict 정량값 | IE6: strict 정량값 | IF6: strict 정량값 | IG6: NO VALUE | IH6: NO VALUE | II6: NO VALUE | IJ6: NO VALUE | IK6: strict 정량값 | IL6: NO VALUE | IM6: strict 정량값 | IN6: strict 정량값 | IO6: strict 정량값 | IP6: strict 정량값 | IQ6: NO VALUE | IR6: strict 정량값 | IS6: NO VALUE | IT6: NO VALUE | IU6: NO VALUE | IV6: NO VALUE | IW6: NO VALUE | IX6: strict 정량값 | IY6: strict 정량값 | IZ6: NO VALUE | JA6: NO VALUE | JB6: NO VALUE | JC6: NO VALUE | JD6: NO VALUE | JE6: NO VALUE | JF6: NO VALUE | JG6: NO VALUE | JH6: NO VALUE | JI6: NO VALUE | JJ6: NO VALUE | JK6: NO VALUE | JL6: strict 정량값 | JM6: strict 정량값 | JN6: strict 정량값 | JO6: strict 정량값 | JP6: strict 정량값 | JQ6: strict 정량값 | JR6: strict 정량값

Sheet A_Replicates_EXC
B1: Lot_QC_Summary | C1: QC_Dictionary | D1: A_Replicates | E1: B_Replicates | F1: Density_Replicates | G1: A_Replicates_INCL | H1: A_Replicates_EXC | I1: Metric_Statistics | J1: A_Step_Replicates | K1: A_Step_Statistics | L1: Replicate_Flags | M1: Traceability
B2: A_Replicates_EXC — INCLUSIVE 결과 중 EXCEPTION 값 감사 필터
B3: 30/45 s 등 승인 예외 hold Step을 사용한 inclusive 값만 표시합니다. 이 시트는 제외 목록이 아니라 사용 내역 확인용입니다.
B4: POLICY INCLUSIVE — accepted holds 30,45,60 s, 범위 밖 Torque 점 inclusive 포함. EXCEPTION·CENSORED 값은 표준 60 s Lot 통계·추세·규격 설정에 혼용 금지
B5: lot | C5: repeat | D5: file | E5: test_start | F5: route | G5: data_qc | H5: A_TAU_L_UP | I5: A_TAU_M_UP | J5: A_TAU_H_UP | K5: A_SSI_FIELD_0P2_2 | L5: A_SSI_QC_0P5_5 | M5: A_DU_L | N5: A_DU_M | O5: A_HYS_REL | P5: A_BRK_PEAK | Q5: A_HB_TAUY_UP | R5: A_HB_K_UP | S5: A_HB_N_UP | T5: A_HB_R2_UP | U5: A_HB_R2_DN | V5: A_HB_TAUY_DN | W5: A_HB_K_DN | X5: A_HB_N_DN | Y5: A_HB_TAUY_RATIO | Z5: A_HDI | AA5: A_OVS_L | AB5: A_HB_GRANGE | AC5: A_ETA_MIN_UP | AD5: A_ETA_HIGH | AE5: A_ETA_LOW_DN | AF5: A_STATIC_YIELD_APPROX_UP | AG5: A_POST_SHEAR_STARTUP_STRESS | AH5: A_POST_SHEAR_STRESS_RETENTION | AI5: A_ETA_RECOVERY_LOW | AJ5: A_HYS_AREA_SIGNED | AK5: A_HYS_AREA_ABS | AL5: A_HB_K_RATIO | AM5: A_HB_N_DIFF | AN5: A_HB_TAUY_UP_COMMON | AO5: A_HB_K_UP_COMMON | AP5: A_HB_N_UP_COMMON | AQ5: A_HB_R2_UP_COMMON | AR5: A_HB_TAUY_DN_COMMON | AS5: A_HB_K_DN_COMMON | AT5: A_HB_N_DN_COMMON | AU5: A_HB_R2_DN_COMMON | AV5: A_HB_TAUY_RATIO_COMMON | AW5: A_STARTUP_PLATEAU_UP | AX5: A_POST_SHEAR_PLATEAU | AY5: A_PLATEAU_RETENTION | AZ5: A_TQ_L | BA5: A_RES_L | BB5: A_DUL_FLOOR | BC5: A_EQ_DRIFT_MAX | BD5: A_TEMP_MEAN | BE5: A_TEMP_SPAN | BF5: A_N_QUANT
B6: SYN | C6: 01 | D6: HT-SYN-01.csv | F6: INCLUSIVE | G6: VALID

Sheet Metric_Statistics
B1: Lot_QC_Summary | C1: QC_Dictionary | D1: A_Replicates | E1: B_Replicates | F1: Density_Replicates | G1: A_Replicates_INCL | H1: A_Replicates_EXC | I1: Metric_Statistics | J1: A_Step_Replicates | K1: A_Step_Statistics | L1: Replicate_Flags | M1: Traceability
B2: Metric_Statistics — STRICT/INCLUSIVE 감사용 반복 통계(수식)
B3: 감사·method 검토용 시트입니다. 좌측은 STRICT(60 s·Torque 10–95%) 통계, 우측은 INCLUSIVE 통계와 차이입니다. 일상 판독은 Lot_QC_Summary의 대표 채널 값을 사용합니다. RSD는 0 기준 차이형 지표(zero_ref)에서 'N/A(0 기준)', |Mean|<SD이면 'N/A(|Mean|<SD)'로 표시합니다. Inclusive 평균은 정책이 허용한 값 구분만 집계하고, n Low/High-TQ Ref는 참고값 개수입니다.
B5: Code | C5: Method | D5: Tier | E5: n Strict | F5: Strict Mean | G5: Strict SD | H5: Strict RSD(%) | I5: Strict Min | J5: Strict Max | K5: Strict Range | L5: Strict |Mean| | M5: Strict n(+) | N5: Strict n(−) | O5: Strict 원본 범위 | P5: n Inclusive | Q5: Inclusive Mean | R5: Inclusive SD | S5: Δ Mean (Inclusive−Strict) | T5: n EXC | U5: EXC Mean | V5: n Low-TQ Ref | W5: n High-TQ Ref | X5: Inclusive Min | Y5: Inclusive Max | Z5: Inclusive Range
B6: A_TAU_L_UP | C6: A | D6: T1 | E6: =COUNT('A_Replicates'!BH6:BH6) | F6: =IF(E6=0,"",AVERAGE('A_Replicates'!BH6:BH6)) | G6: =IF(E6<2,"",STDEV('A_Replicates'!BH6:BH6)) | H6: =IF(E6<2,"",IF(G6=0,0,IF(ABS(F6)<G6,"N/A(|Mean|<SD)",G6/ABS(F6)*100))) | I6: =IF(E6=0,"",MIN('A_Replicates'!BH6:BH6)) | J6: =IF(E6=0,"",MAX('A_Replicates'!BH6:BH6)) | K6: =IF(E6=0,"",J6-I6) | L6: =IF(E6=0,"",SUMPRODUCT(ABS('A_Replicates'!BH6:BH6))/E6) | M6: =IF(E6=0,"",COUNTIF('A_Replicates'!BH6:BH6,">0")) | N6: =IF(E6=0,"",COUNTIF('A_Replicates'!BH6:BH6,"<0")) | O6: 'A_Replicates'!BH6:BH6 | P6: =COUNT('A_Replicates_INCL'!BH6:BH6) | Q6: =IF(P6=0,"",AVERAGE('A_Replicates_INCL'!BH6:BH6)) | R6: =IF(P6<2,"",STDEV('A_Replicates_INCL'!BH6:BH6)) | S6: =IF(OR(P6=0,E6=0),"",Q6-F6) | T6: =COUNT('A_Replicates_EXC'!H6:H6) | U6: =IF(T6=0,"",AVERAGE('A_Replicates_EXC'!H6:H6)) | V6: =COUNTIF('A_Replicates_INCL'!HT6:HT6,"torque 하한 밖 참고값")+COUNTIF('A_Replicates_INCL'!HT6:HT6,"torque 범위 밖 참고값") | W6: =COUNTIF('A_Replicates_INCL'!HT6:HT6,"torque 상한 밖 참고값")+COUNTIF('A_Replicates_INCL'!HT6:HT6,"torque 범위 밖 참고값") | X6: =IF(P6=0,"",MIN('A_Replicates_INCL'!BH6:BH6)) | Y6: =IF(P6=0,"",MAX('A_Replicates_INCL'!BH6:BH6)) | Z6: =IF(P6=0,"",Y6-X6)
B7: A_TAU_M_UP | C7: A | D7: T1 | E7: =COUNT('A_Replicates'!BK6:BK6) | F7: =IF(E7=0,"",AVERAGE('A_Replicates'!BK6:BK6)) | G7: =IF(E7<2,"",STDEV('A_Replicates'!BK6:BK6)) | H7: =IF(E7<2,"",IF(G7=0,0,IF(ABS(F7)<G7,"N/A(|Mean|<SD)",G7/ABS(F7)*100))) | I7: =IF(E7=0,"",MIN('A_Replicates'!BK6:BK6)) | J7: =IF(E7=0,"",MAX('A_Replicates'!BK6:BK6)) | K7: =IF(E7=0,"",J7-I7) | L7: =IF(E7=0,"",SUMPRODUCT(ABS('A_Replicates'!BK6:BK6))/E7) | M7: =IF(E7=0,"",COUNTIF('A_Replicates'!BK6:BK6,">0")) | N7: =IF(E7=0,"",COUNTIF('A_Replicates'!BK6:BK6,"<0")) | O7: 'A_Replicates'!BK6:BK6 | P7: =COUNT('A_Replicates_INCL'!BK6:BK6) | Q7: =IF(P7=0,"",AVERAGE('A_Replicates_INCL'!BK6:BK6)) | R7: =IF(P7<2,"",STDEV('A_Replicates_INCL'!BK6:BK6)) | S7: =IF(OR(P7=0,E7=0),"",Q7-F7) | T7: =COUNT('A_Replicates_EXC'!I6:I6) | U7: =IF(T7=0,"",AVERAGE('A_Replicates_EXC'!I6:I6)) | V7: =COUNTIF('A_Replicates_INCL'!HU6:HU6,"torque 하한 밖 참고값")+COUNTIF('A_Replicates_INCL'!HU6:HU6,"torque 범위 밖 참고값") | W7: =COUNTIF('A_Replicates_INCL'!HU6:HU6,"torque 상한 밖 참고값")+COUNTIF('A_Replicates_INCL'!HU6:HU6,"torque 범위 밖 참고값") | X7: =IF(P7=0,"",MIN('A_Replicates_INCL'!BK6:BK6)) | Y7: =IF(P7=0,"",MAX('A_Replicates_INCL'!BK6:BK6)) | Z7: =IF(P7=0,"",Y7-X7)
B8: A_TAU_H_UP | C8: A | D8: T1 | E8: =COUNT('A_Replicates'!BN6:BN6) | F8: =IF(E8=0,"",AVERAGE('A_Replicates'!BN6:BN6)) | G8: =IF(E8<2,"",STDEV('A_Replicates'!BN6:BN6)) | H8: =IF(E8<2,"",IF(G8=0,0,IF(ABS(F8)<G8,"N/A(|Mean|<SD)",G8/ABS(F8)*100))) | I8: =IF(E8=0,"",MIN('A_Replicates'!BN6:BN6)) | J8: =IF(E8=0,"",MAX('A_Replicates'!BN6:BN6)) | K8: =IF(E8=0,"",J8-I8) | L8: =IF(E8=0,"",SUMPRODUCT(ABS('A_Replicates'!BN6:BN6))/E8) | M8: =IF(E8=0,"",COUNTIF('A_Replicates'!BN6:BN6,">0")) | N8: =IF(E8=0,"",COUNTIF('A_Replicates'!BN6:BN6,"<0")) | O8: 'A_Replicates'!BN6:BN6 | P8: =COUNT('A_Replicates_INCL'!BN6:BN6) | Q8: =IF(P8=0,"",AVERAGE('A_Replicates_INCL'!BN6:BN6)) | R8: =IF(P8<2,"",STDEV('A_Replicates_INCL'!BN6:BN6)) | S8: =IF(OR(P8=0,E8=0),"",Q8-F8) | T8: =COUNT('A_Replicates_EXC'!J6:J6) | U8: =IF(T8=0,"",AVERAGE('A_Replicates_EXC'!J6:J6)) | V8: =COUNTIF('A_Replicates_INCL'!HV6:HV6,"torque 하한 밖 참고값")+COUNTIF('A_Replicates_INCL'!HV6:HV6,"torque 범위 밖 참고값") | W8: =COUNTIF('A_Replicates_INCL'!HV6:HV6,"torque 상한 밖 참고값")+COUNTIF('A_Replicates_INCL'!HV6:HV6,"torque 범위 밖 참고값") | X8: =IF(P8=0,"",MIN('A_Replicates_INCL'!BN6:BN6)) | Y8: =IF(P8=0,"",MAX('A_Replicates_INCL'!BN6:BN6)) | Z8: =IF(P8=0,"",Y8-X8)
B9: A_ETA_MIN_UP | C9: A | D9: T1 | E9: =COUNT('A_Replicates'!DS6:DS6) | F9: =IF(E9=0,"",AVERAGE('A_Replicates'!DS6:DS6)) | G9: =IF(E9<2,"",STDEV('A_Replicates'!DS6:DS6)) | H9: =IF(E9<2,"",IF(G9=0,0,IF(ABS(F9)<G9,"N/A(|Mean|<SD)",G9/ABS(F9)*100))) | I9: =IF(E9=0,"",MIN('A_Replicates'!DS6:DS6)) | J9: =IF(E9=0,"",MAX('A_Replicates'!DS6:DS6)) | K9: =IF(E9=0,"",J9-I9) | L9: =IF(E9=0,"",SUMPRODUCT(ABS('A_Replicates'!DS6:DS6))/E9) | M9: =IF(E9=0,"",COUNTIF('A_Replicates'!DS6:DS6,">0")) | N9: =IF(E9=0,"",COUNTIF('A_Replicates'!DS6:DS6,"<0")) | O9: 'A_Replicates'!DS6:DS6 | P9: =COUNT('A_Replicates_INCL'!DS6:DS6) | Q9: =IF(P9=0,"",AVERAGE('A_Replicates_INCL'!DS6:DS6)) | R9: =IF(P9<2,"",STDEV('A_Replicates_INCL'!DS6:DS6)) | S9: =IF(OR(P9=0,E9=0),"",Q9-F9) | T9: =COUNT('A_Replicates_EXC'!AC6:AC6) | U9: =IF(T9=0,"",AVERAGE('A_Replicates_EXC'!AC6:AC6)) | V9: =COUNTIF('A_Replicates_INCL'!IO6:IO6,"torque 하한 밖 참고값")+COUNTIF('A_Replicates_INCL'!IO6:IO6,"torque 범위 밖 참고값") | W9: =COUNTIF('A_Replicates_INCL'!IO6:IO6,"torque 상한 밖 참고값")+COUNTIF('A_Replicates_INCL'!IO6:IO6,"torque 범위 밖 참고값") | X9: =IF(P9=0,"",MIN('A_Replicates_INCL'!DS6:DS6)) | Y9: =IF(P9=0,"",MAX('A_Replicates_INCL'!DS6:DS6)) | Z9: =IF(P9=0,"",Y9-X9)
B10: A_ETA_HIGH | C10: A | D10: T1 | E10: =COUNT('A_Replicates'!DV6:DV6) | F10: =IF(E10=0,"",AVERAGE('A_Replicates'!DV6:DV6)) | G10: =IF(E10<2,"",STDEV('A_Replicates'!DV6:DV6)) | H10: =IF(E10<2,"",IF(G10=0,0,IF(ABS(F10)<G10,"N/A(|Mean|<SD)",G10/ABS(F10)*100))) | I10: =IF(E10=0,"",MIN('A_Replicates'!DV6:DV6)) | J10: =IF(E10=0,"",MAX('A_Replicates'!DV6:DV6)) | K10: =IF(E10=0,"",J10-I10) | L10: =IF(E10=0,"",SUMPRODUCT(ABS('A_Replicates'!DV6:DV6))/E10) | M10: =IF(E10=0,"",COUNTIF('A_Replicates'!DV6:DV6,">0")) | N10: =IF(E10=0,"",COUNTIF('A_Replicates'!DV6:DV6,"<0")) | O10: 'A_Replicates'!DV6:DV6 | P10: =COUNT('A_Replicates_INCL'!DV6:DV6) | Q10: =IF(P10=0,"",AVERAGE('A_Replicates_INCL'!DV6:DV6)) | R10: =IF(P10<2,"",STDEV('A_Replicates_INCL'!DV6:DV6)) | S10: =IF(OR(P10=0,E10=0),"",Q10-F10) | T10: =COUNT('A_Replicates_EXC'!AD6:AD6) | U10: =IF(T10=0,"",AVERAGE('A_Replicates_EXC'!AD6:AD6)) | V10: =COUNTIF('A_Replicates_INCL'!IP6:IP6,"torque 하한 밖 참고값")+COUNTIF('A_Replicates_INCL'!IP6:IP6,"torque 범위 밖 참고값") | W10: =COUNTIF('A_Replicates_INCL'!IP6:IP6,"torque 상한 밖 참고값")+COUNTIF('A_Replicates_INCL'!IP6:IP6,"torque 범위 밖 참고값") | X10: =IF(P10=0,"",MIN('A_Replicates_INCL'!DV6:DV6)) | Y10: =IF(P10=0,"",MAX('A_Replicates_INCL'!DV6:DV6)) | Z10: =IF(P10=0,"",Y10-X10)
B11: A_SSI_FIELD_0P2_2 | C11: A | D11: T1 | E11: =COUNT('A_Replicates'!BQ6:BQ6) | F11: =IF(E11=0,"",AVERAGE('A_Replicates'!BQ6:BQ6)) | G11: =IF(E11<2,"",STDEV('A_Replicates'!BQ6:BQ6)) | H11: =IF(E11<2,"",IF(G11=0,0,IF(ABS(F11)<G11,"N/A(|Mean|<SD)",G11/ABS(F11)*100))) | I11: =IF(E11=0,"",MIN('A_Replicates'!BQ6:BQ6)) | J11: =IF(E11=0,"",MAX('A_Replicates'!BQ6:BQ6)) | K11: =IF(E11=0,"",J11-I11) | L11: =IF(E11=0,"",SUMPRODUCT(ABS('A_Replicates'!BQ6:BQ6))/E11) | M11: =IF(E11=0,"",COUNTIF('A_Replicates'!BQ6:BQ6,">0")) | N11: =IF(E11=0,"",COUNTIF('A_Replicates'!BQ6:BQ6,"<0")) | O11: 'A_Replicates'!BQ6:BQ6 | P11: =COUNT('A_Replicates_INCL'!BQ6:BQ6) | Q11: =IF(P11=0,"",AVERAGE('A_Replicates_INCL'!BQ6:BQ6)) | R11: =IF(P11<2,"",STDEV('A_Replicates_INCL'!BQ6:BQ6)) | S11: =IF(OR(P11=0,E11=0),"",Q11-F11) | T11: =COUNT('A_Replicates_EXC'!K6:K6) | U11: =IF(T11=0,"",AVERAGE('A_Replicates_EXC'!K6:K6)) | V11: =COUNTIF('A_Replicates_INCL'!HW6:HW6,"torque 하한 밖 참고값")+COUNTIF('A_Replicates_INCL'!HW6:HW6,"torque 범위 밖 참고값") | W11: =COUNTIF('A_Replicates_INCL'!HW6:HW6,"torque 상한 밖 참고값")+COUNTIF('A_Replicates_INCL'!HW6:HW6,"torque 범위 밖 참고값") | X11: =IF(P11=0,"",MIN('A_Replicates_INCL'!BQ6:BQ6)) | Y11: =IF(P11=0,"",MAX('A_Replicates_INCL'!BQ6:BQ6)) | Z11: =IF(P11=0,"",Y11-X11)
B12: A_SSI_QC_0P5_5 | C12: A | D12: T1 | E12: =COUNT('A_Replicates'!BT6:BT6) | F12: =IF(E12=0,"",AVERAGE('A_Replicates'!BT6:BT6)) | G12: =IF(E12<2,"",STDEV('A_Replicates'!BT6:BT6)) | H12: =IF(E12<2,"",IF(G12=0,0,IF(ABS(F12)<G12,"N/A(|Mean|<SD)",G12/ABS(F12)*100))) | I12: =IF(E12=0,"",MIN('A_Replicates'!BT6:BT6)) | J12: =IF(E12=0,"",MAX('A_Replicates'!BT6:BT6)) | K12: =IF(E12=0,"",J12-I12) | L12: =IF(E12=0,"",SUMPRODUCT(ABS('A_Replicates'!BT6:BT6))/E12) | M12: =IF(E12=0,"",COUNTIF('A_Replicates'!BT6:BT6,">0")) | N12: =IF(E12=0,"",COUNTIF('A_Replicates'!BT6:BT6,"<0")) | O12: 'A_Replicates'!BT6:BT6 | P12: =COUNT('A_Replicates_INCL'!BT6:BT6) | Q12: =IF(P12=0,"",AVERAGE('A_Replicates_INCL'!BT6:BT6)) | R12: =IF(P12<2,"",STDEV('A_Replicates_INCL'!BT6:BT6)) | S12: =IF(OR(P12=0,E12=0),"",Q12-F12) | T12: =COUNT('A_Replicates_EXC'!L6:L6) | U12: =IF(T12=0,"",AVERAGE('A_Replicates_EXC'!L6:L6)) | V12: =COUNTIF('A_Replicates_INCL'!HX6:HX6,"torque 하한 밖 참고값")+COUNTIF('A_Replicates_INCL'!HX6:HX6,"torque 범위 밖 참고값") | W12: =COUNTIF('A_Replicates_INCL'!HX6:HX6,"torque 상한 밖 참고값")+COUNTIF('A_Replicates_INCL'!HX6:HX6,"torque 범위 밖 참고값") | X12: =IF(P12=0,"",MIN('A_Replicates_INCL'!BT6:BT6)) | Y12: =IF(P12=0,"",MAX('A_Replicates_INCL'!BT6:BT6)) | Z12: =IF(P12=0,"",Y12-X12)
B13: A_ETA_LOW_DN | C13: A | D13: T1 | E13: =COUNT('A_Replicates'!DY6:DY6) | F13: =IF(E13=0,"",AVERAGE('A_Replicates'!DY6:DY6)) | G13: =IF(E13<2,"",STDEV('A_Replicates'!DY6:DY6)) | H13: =IF(E13<2,"",IF(G13=0,0,IF(ABS(F13)<G13,"N/A(|Mean|<SD)",G13/ABS(F13)*100))) | I13: =IF(E13=0,"",MIN('A_Replicates'!DY6:DY6)) | J13: =IF(E13=0,"",MAX('A_Replicates'!DY6:DY6)) | K13: =IF(E13=0,"",J13-I13) | L13: =IF(E13=0,"",SUMPRODUCT(ABS('A_Replicates'!DY6:DY6))/E13) | M13: =IF(E13=0,"",COUNTIF('A_Replicates'!DY6:DY6,">0")) | N13: =IF(E13=0,"",COUNTIF('A_Replicates'!DY6:DY6,"<0")) | O13: 'A_Replicates'!DY6:DY6 | P13: =COUNT('A_Replicates_INCL'!DY6:DY6) | Q13: =IF(P13=0,"",AVERAGE('A_Replicates_INCL'!DY6:DY6)) | R13: =IF(P13<2,"",STDEV('A_Replicates_INCL'!DY6:DY6)) | S13: =IF(OR(P13=0,E13=0),"",Q13-F13) | T13: =COUNT('A_Replicates_EXC'!AE6:AE6) | U13: =IF(T13=0,"",AVERAGE('A_Replicates_EXC'!AE6:AE6)) | V13: =COUNTIF('A_Replicates_INCL'!IQ6:IQ6,"torque 하한 밖 참고값")+COUNTIF('A_Replicates_INCL'!IQ6:IQ6,"torque 범위 밖 참고값") | W13: =COUNTIF('A_Replicates_INCL'!IQ6:IQ6,"torque 상한 밖 참고값")+COUNTIF('A_Replicates_INCL'!IQ6:IQ6,"torque 범위 밖 참고값") | X13: =IF(P13=0,"",MIN('A_Replicates_INCL'!DY6:DY6)) | Y13: =IF(P13=0,"",MAX('A_Replicates_INCL'!DY6:DY6)) | Z13: =IF(P13=0,"",Y13-X13)
